Workbook

Sheet Marksheet
A1: Final Marks
A2: Physics for Computer Engineers (PHYS 1036)
A3: Name | B3: SAP ID | C3: Batch | D3: Quiz 1 | E3: Assignment 1 | F3: Class Test 1 | G3: Quiz 2 | H3: Assignment 2 | I3: Class Test 2 | J3: IA | K3: Lab | L3: CIA | M3: CIA_Weightage | N3: Mid Sem | O3: Mid Sem | P3: End Sem | Q3: End Sem | R3: Total | S3: Sign | U3: Email Address | V3: Roll Number
B4: Max Marks | D4: 15 | E4: 15 | F4: 20 | G4: ='Quiz 2'!O5 -> 15 | H4: ='Assignment 2'!N5 -> 15 | I4: ='Class Test 2'!O5 -> 20 | J4: =SUM(D4:I4) -> 100 | K4: 100 | L4: =SUM(J4:K4)/2 -> 100 | M4: =L4*0.5 -> 50 | N4: =O4/5 -> 20 | O4: 100 | P4: 100 | Q4: =P4*0.3 -> 30 | R4: =SUM(M4,N4,Q4) -> 100
A5: Aadya Dubey | B5: 590029213 | C5: 77 | D5: ='Quiz 1'!O6 -> 14.5 | E5: ='Assignment 1'!N6/10 -> 14.5 | F5: ='Class Test 1'!P6 -> 20 | G5: ='Quiz 2'!O6 -> 15 | H5: ='Assignment 2'!N6 -> 15 | I5: ='Class Test 2'!O6 -> 15 | J5: =SUM(D5:I5) -> 94 | K5: 95.5 | L5: =SUM(J5:K5)/2 -> 94.75 | M5: =L5*0.5 -> 47.375 | N5: =O5/5 -> 17.2 | O5: ='Mid Sem'!O6 -> 86 | P5: ='End Sem'!N6 -> 0 | Q5: =P5*0.3 -> 0 | R5: =SUM(M5,N5,Q5) -> 64.575 | U5: aadya.29213@stu.upes.ac.in | V5: 122507103
A6: Aditya Vishwakarma | B6: 590029270 | C6: 77 | D6: ='Quiz 1'!O7 -> 15 | E6: ='Assignment 1'!N7/10 -> 14 | F6: ='Class Test 1'!P7 -> 12 | G6: ='Quiz 2'!O7 -> 15 | H6: ='Assignment 2'!N7 -> 15 | I6: ='Class Test 2'!O7 -> 11.5 | J6: =SUM(D6:I6) -> 82.5 | K6: 39 | L6: =SUM(J6:K6)/2 -> 60.75 | M6: =L6*0.5 -> 30.375 | N6: =O6/5 -> 6.4 | O6: ='Mid Sem'!O7 -> 32 | P6: ='End Sem'!N7 -> 0 | Q6: =P6*0.3 -> 0 | R6: =SUM(M6,N6,Q6) -> 36.775 | U6: aditya.29270@stu.upes.ac.in | V6: 25010104938
A7: Arjun | B7: 590029204 | C7: 77 | D7: ='Quiz 1'!O8 -> 8 | E7: ='Assignment 1'!N8/10 -> 14.2 | F7: ='Class Test 1'!P8 -> 7 | G7: ='Quiz 2'!O8 -> 10.5 | H7: ='Assignment 2'!N8 -> 14 | I7: ='Class Test 2'!O8 -> 11.5 | J7: =SUM(D7:I7) -> 65.2 | K7: 73.5 | L7: =SUM(J7:K7)/2 -> 69.35 | M7: =L7*0.5 -> 34.675 | N7: =O7/5 -> 5.8 | O7: ='Mid Sem'!O8 -> 29 | P7: ='End Sem'!N8 -> 0 | Q7: =P7*0.3 -> 0 | R7: =SUM(M7,N7,Q7) -> 40.475 | U7: arjun.29204@stu.upes.ac.in | V7: 25010104918
A8: Aryan Yadav | B8: 590029109 | C8: 77 | D8: ='Quiz 1'!O9 -> 11 | E8: ='Assignment 1'!N9/10 -> 15 | F8: ='Class Test 1'!P9 -> 15 | G8: ='Quiz 2'!O9 -> 15 | H8: ='Assignment 2'!N9 -> 15 | I8: ='Class Test 2'!O9 -> 0 | J8: =SUM(D8:I8) -> 71 | K8: 54.5 | L8: =SUM(J8:K8)/2 -> 62.75 | M8: =L8*0.5 -> 31.375 | N8: =O8/5 -> 7.6 | O8: ='Mid Sem'!O9 -> 38 | P8: ='End Sem'!N9 -> 0 | Q8: =P8*0.3 -> 0 | R8: =SUM(M8,N8,Q8) -> 38.975 | U8: aryan.29109@stu.upes.ac.in | V8: 25010104943
A9: Astik Patel | B9: 590029070 | C9: 77 | D9: ='Quiz 1'!O10 -> 13 | E9: ='Assignment 1'!N10/10 -> 14.2 | F9: ='Class Test 1'!P10 -> 16 | G9: ='Quiz 2'!O10 -> 15 | H9: ='Assignment 2'!N10 -> 15 | I9: ='Class Test 2'!O10 -> 17.5 | J9: =SUM(D9:I9) -> 90.7 | K9: 97.5 | L9: =SUM(J9:K9)/2 -> 94.1 | M9: =L9*0.5 -> 47.05 | N9: =O9/5 -> 18 | O9: ='Mid Sem'!O10 -> 90 | P9: ='End Sem'!N10 -> 0 | Q9: =P9*0.3 -> 0 | R9: =SUM(M9,N9,Q9) -> 65.05 | U9: astik.29070@stu.upes.ac.in | V9: 25010104926
A10: Ayush Mohan | B10: 590029157 | C10: 77 | D10: ='Quiz 1'!O11 -> 15 | E10: ='Assignment 1'!N11/10 -> 13.6 | F10: ='Class Test 1'!P11 -> 12 | G10: ='Quiz 2'!O11 -> 12.5 | H10: ='Assignment 2'!N11 -> 15 | I10: ='Class Test 2'!O11 -> 15.5 | J10: =SUM(D10:I10) -> 83.6 | K10: 40 | L10: =SUM(J10:K10)/2 -> 61.8 | M10: =L10*0.5 -> 30.9 | N10: =O10/5 -> 2.8 | O10: ='Mid Sem'!O11 -> 14 | P10: ='End Sem'!N11 -> 0 | Q10: =P10*0.3 -> 0 | R10: =SUM(M10,N10,Q10) -> 33.7 | U10: ayush.29157@stu.upes.ac.in | V10: 25010104890
A11: Bhanu Purohit | B11: 590027157 | C11: 77 | D11: ='Quiz 1'!O12 -> 8.5 | E11: ='Assignment 1'!N12/10 -> 13.9 | F11: ='Class Test 1'!P12 -> 14 | G11: ='Quiz 2'!O12 -> 10 | H11: ='Assignment 2'!N12 -> 0 | I11: ='Class Test 2'!O12 -> 0 | J11: =SUM(D11:I11) -> 46.4 | K11: 54 | L11: =SUM(J11:K11)/2 -> 50.2 | M11: =L11*0.5 -> 25.1 | N11: =O11/5 -> 10 | O11: ='Mid Sem'!O12 -> 50 | P11: ='End Sem'!N12 -> 0 | Q11: =P11*0.3 -> 0 | R11: =SUM(M11,N11,Q11) -> 35.1 | U11: bhanu.27157@stu.upes.ac.in | V11: 25010104880
A12: Biswabandya Mohanty | B12: 590029274 | C12: 77 | D12: ='Quiz 1'!O13 -> 8.5 | E12: ='Assignment 1'!N13/10 -> 13.8 | F12: ='Class Test 1'!P13 -> 19 | G12: ='Quiz 2'!O13 -> 14 | H12: ='Assignment 2'!N13 -> 15 | I12: ='Class Test 2'!O13 -> 10.5 | J12: =SUM(D12:I12) -> 80.8 | K12: 44.5 | L12: =SUM(J12:K12)/2 -> 62.65 | M12: =L12*0.5 -> 31.325 | N12: =O12/5 -> 1.6 | O12: ='Mid Sem'!O13 -> 8 | P12: ='End Sem'!N13 -> 0 | Q12: =P12*0.3 -> 0 | R12: =SUM(M12,N12,Q12) -> 32.925 | U12: biswabandya.29274@stu.upes.ac.in | V12: 25010104928
A13: Eashan Vashisht | B13: 590028572 | C13: 77 | D13: ='Quiz 1'!O14 -> 12 | E13: ='Assignment 1'!N14/10 -> 14.5 | F13: ='Class Test 1'!P14 -> 20 | G13: ='Quiz 2'!O14 -> 12 | H13: ='Assignment 2'!N14 -> 15 | I13: ='Class Test 2'!O14 -> 18.5 | J13: =SUM(D13:I13) -> 92 | K13: 98 | L13: =SUM(J13:K13)/2 -> 95 | M13: =L13*0.5 -> 47.5 | N13: =O13/5 -> 10.8 | O13: ='Mid Sem'!O14 -> 54 | P13: ='End Sem'!N14 -> 0 | Q13: =P13*0.3 -> 0 | R13: =SUM(M13,N13,Q13) -> 58.3 | U13: eashan.28572@stu.upes.ac.in | V13: 25010104903
A14: Hardik Joshi | B14: 590029230 | C14: 77 | D14: ='Quiz 1'!O15 -> 0 | E14: ='Assignment 1'!N15/10 -> 0 | F14: ='Class Test 1'!P15 -> 0 | G14: ='Quiz 2'!O15 -> 0 | H14: ='Assignment 2'!N15 -> 0 | I14: ='Class Test 2'!O15 -> 0 | J14: =SUM(D14:I14) -> 0 | K14: 0 | L14: =SUM(J14:K14)/2 -> 0 | M14: =L14*0.5 -> 0 | N14: =O14/5 -> 0 | O14: ='Mid Sem'!O15 -> 0 | P14: ='End Sem'!N15 -> 0 | Q14: =P14*0.3 -> 0 | R14: =SUM(M14,N14,Q14) -> 0 | U14: hardik.29230@stu.upes.ac.in | V14: 25010104910
A15: Hrithvik Bhardwaj | B15: 590029169 | C15: 77 | D15: ='Quiz 1'!O16 -> 10.5 | E15: ='Assignment 1'!N16/10 -> 13.7 | F15: ='Class Test 1'!P16 -> 9 | G15: ='Quiz 2'!O16 -> 13 | H15: ='Assignment 2'!N16 -> 15 | I15: ='Class Test 2'!O16 -> 10.5 | J15: =SUM(D15:I15) -> 71.7 | K15: 39 | L15: =SUM(J15:K15)/2 -> 55.35 | M15: =L15*0.5 -> 27.675 | N15: =O15/5 -> 0.2 | O15: ='Mid Sem'!O16 -> 1 | P15: ='End Sem'!N16 -> 0 | Q15: =P15*0.3 -> 0 | R15: =SUM(M15,N15,Q15) -> 27.875 | U15: hrithvik.29169@stu.upes.ac.in | V15: 25010104944
A16: Nitish Kumar | B16: 590029112 | C16: 77 | D16: ='Quiz 1'!O17 -> 12 | E16: ='Assignment 1'!N17/10 -> 13.4 | F16: ='Class Test 1'!P17 -> 15 | G16: ='Quiz 2'!O17 -> 6 | H16: ='Assignment 2'!N17 -> 14 | I16: ='Class Test 2'!O17 -> 15 | J16: =SUM(D16:I16) -> 75.4 | K16: 65 | L16: =SUM(J16:K16)/2 -> 70.2 | M16: =L16*0.5 -> 35.1 | N16: =O16/5 -> 7 | O16: ='Mid Sem'!O17 -> 35 | P16: ='End Sem'!N17 -> 0 | Q16: =P16*0.3 -> 0 | R16: =SUM(M16,N16,Q16) -> 42.1 | U16: nitish.29112@stu.upes.ac.in | V16: 25010104876
... A63: Vinit Kumar | B63: 590029353 | C63: 78 | D63: ='Quiz 1'!O64 -> 14 | E63: ='Assignment 1'!N64/10 -> 14.5 | F63: ='Class Test 1'!P64 -> 17 | G63: ='Quiz 2'!O64 -> 0 | H63: ='Assignment 2'!N64 -> 15 | I63: ='Class Test 2'!O64 -> 15 | J63: =SUM(D63:I63) -> 75.5 | K63: 70 | L63: =SUM(J63:K63)/2 -> 72.75 | M63: =L63*0.5 -> 36.375 | N63: =O63/5 -> 2.6 | O63: ='Mid Sem'!O64 -> 13 | P63: ='End Sem'!N64 -> 0 | Q63: =P63*0.3 -> 0 | R63: =SUM(M63,N63,Q63) -> 38.975 | U63: vinit.29353@stu.upes.ac.in | V63: 122514758
C65: Max | D65: =MAX(D5:D63) -> 15 | E65: =MAX(E5:E63) -> 15 | F65: =MAX(F5:F63) -> 20 | G65: =MAX(G5:G63) -> 15 | H65: =MAX(H5:H63) -> 15 | I65: =MAX(I5:I63) -> 19.5 | J65: =MAX(J5:J63) -> 97.8 | K65: =MAX(K5:K63) -> 98 | ... S65: =MAX(S5:S63) -> 0
C66: Min | D66: =_xlfn.MINIFS(D5:D63, D5:D63, ">0") -> 5 | E66: =_xlfn.MINIFS(E5:E63, E5:E63, ">0") -> 5.1 | F66: =_xlfn.MINIFS(F5:F63, F5:F63, ">0") -> 2 | G66: =_xlfn.MINIFS(G5:G63, G5:G63, ">0") -> 6 | H66: =_xlfn.MINIFS(H5:H63, H5:H63, ">0") -> 14 | I66: =_xlfn.MINIFS(I5:I63, I5:I63, ">0") -> 3 | J66: =_xlfn.MINIFS(J5:J63, J5:J63, ">0") -> 17.5 | K66: =_xlfn.MINIFS(K5:K63, K5:K63, ">0") -> 5 | ... S66: =_xlfn.MINIFS(S5:S63, S5:S63, ">0") -> 0
C67: Median | D67: =MEDIAN(D5:D63) -> 11 | E67: =MEDIAN(E5:E63) -> 13.8 | F67: =MEDIAN(F5:F63) -> 12.5 | G67: =MEDIAN(G5:G63) -> 12.5 | H67: =MEDIAN(H5:H63) -> 15 | I67: =MEDIAN(I5:I63) -> 14 | J67: =MEDIAN(J5:J63) -> 72.2 | K67: =MEDIAN(K5:K63) -> 52.5 | ... S67: =MEDIAN(S5:S63) -> #NUM!
C68: Median | D68: {=MEDIAN(_xlfn._xlws.FILTER(D5:D63, D5:D63<>0))} -> 12 | E68: {=MEDIAN(_xlfn._xlws.FILTER(E5:E63, E5:E63<>0))} -> 14 | F68: {=MEDIAN(_xlfn._xlws.FILTER(F5:F63, F5:F63<>0))} -> 14.25 | G68: {=MEDIAN(_xlfn._xlws.FILTER(G5:G63, G5:G63<>0))} -> 13.5 | H68: {=MEDIAN(_xlfn._xlws.FILTER(H5:H63, H5:H63<>0))} -> 15 | I68: {=MEDIAN(_xlfn._xlws.FILTER(I5:I63, I5:I63<>0))} -> 14.5 | J68: {=MEDIAN(_xlfn._xlws.FILTER(J5:J63, J5:J63<>0))} -> 75.5 | K68: {=MEDIAN(_xlfn._xlws.FILTER(K5:K63, K5:K63<>0))} -> 53.5 | ... R68: {=MEDIAN(_xlfn._xlws.FILTER(R5:R63, R5:R63<>0))} -> 38.975

Sheet Quiz 1
A1: Quiz 1
A2: =Marksheet!A2 -> Physics for Computer Engineers (PHYS 1036)
D3: CO1 | E3: CO1 | F3: CO1 | G3: CO1 | H3: CO2 | I3: CO2 | J3: CO2 | K3: CO1 | L3: CO2 | M3: CO1 | S3: CO1 | T3: CO2
A4: Student Id | B4: Name | D4: Q1 | E4: Q2 | F4: Q3 | G4: Q4 | H4: Q5 | I4: Q6 | J4: Q7 | K4: Q8 | L4: Q9 | M4: Q10 | N4: Q11 | O4: Total | P4: Sign | U4: Total
B5: Max Marks | C5: P/A | D5: 1 | E5: 1 | F5: 1 | G5: 1 | H5: 1 | I5: 1 | J5: 1 | K5: 2.5 | L5: 2.5 | M5: 3 | O5: =SUM(D5:N5) -> 15 | S5: =SUM(D5:G5,K5,M5) -> 9.5 | T5: =SUM(H5,I5,J5,L5) -> 5.5 | U5: =SUM(S5:T5) -> 15
A6: ='Mid Sem'!B6 -> 590029213 | B6: ='Mid Sem'!A6 -> Aadya Dubey | C6: TRUE | D6: 0.5 | E6: 1 | F6: 1 | G6: 1 | H6: 1 | I6: 1 | J6: 1 | K6: 2.5 | L6: 2.5 | M6: 3 | O6: =SUM(D6:N6) -> 14.5 | S6: =SUM(D6:G6,K6,M6) -> 9 | T6: =SUM(H6,I6,J6,L6) -> 5.5 | U6: =SUM(S6:T6) -> 14.5
A7: ='Mid Sem'!B7 -> 590029270 | B7: ='Mid Sem'!A7 -> Aditya Vishwakarma | C7: TRUE | D7: 1 | E7: 1 | F7: 1 | G7: 1 | H7: 1 | I7: 1 | J7: 1 | K7: 2.5 | L7: 2.5 | M7: 3 | O7: =SUM(D7:N7) -> 15 | S7: =SUM(D7:G7,K7,M7) -> 9.5 | T7: =SUM(H7,I7,J7,L7) -> 5.5 | U7: =SUM(S7:T7) -> 15
A8: ='Mid Sem'!B8 -> 590029204 | B8: ='Mid Sem'!A8 -> Arjun | C8: TRUE | D8: 0 | E8: 1 | F8: 1 | G8: 0 | H8: 1 | I8: 1 | J8: 1 | K8: 0 | L8: 1 | M8: 2 | O8: =SUM(D8:N8) -> 8 | S8: =SUM(D8:G8,K8,M8) -> 4 | T8: =SUM(H8,I8,J8,L8) -> 4 | U8: =SUM(S8:T8) -> 8
A9: ='Mid Sem'!B9 -> 590029109 | B9: ='Mid Sem'!A9 -> Aryan Yadav | C9: TRUE | D9: 1 | E9: 1 | F9: 1 | G9: 1 | H9: 1 | I9: 1 | J9: 1 | K9: 1.5 | L9: 2.5 | M9: 0 | O9: =SUM(D9:N9) -> 11 | S9: =SUM(D9:G9,K9,M9) -> 5.5 | T9: =SUM(H9,I9,J9,L9) -> 5.5 | U9: =SUM(S9:T9) -> 11
A10: ='Mid Sem'!B10 -> 590029070 | B10: ='Mid Sem'!A10 -> Astik Patel | C10: TRUE | D10: 1 | E10: 1 | F10: 0 | G10: 1 | H10: 1 | I10: 1 | J10: 1 | K10: 2.5 | L10: 2.5 | M10: 2 | O10: =SUM(D10:N10) -> 13 | S10: =SUM(D10:G10,K10,M10) -> 7.5 | T10: =SUM(H10,I10,J10,L10) -> 5.5 | U10: =SUM(S10:T10) -> 13
A11: ='Mid Sem'!B11 -> 590029157 | B11: ='Mid Sem'!A11 -> Ayush Mohan | C11: TRUE | D11: 1 | E11: 1 | F11: 1 | G11: 1 | H11: 1 | I11: 1 | J11: 1 | K11: 2.5 | L11: 2.5 | M11: 3 | O11: =SUM(D11:N11) -> 15 | S11: =SUM(D11:G11,K11,M11) -> 9.5 | T11: =SUM(H11,I11,J11,L11) -> 5.5 | U11: =SUM(S11:T11) -> 15
A12: ='Mid Sem'!B12 -> 590027157 | B12: ='Mid Sem'!A12 -> Bhanu Purohit | C12: TRUE | D12: 1 | E12: 1 | F12: 1 | G12: 0 | H12: 1 | I12: 1 | J12: 1 | K12: 0.5 | L12: 0 | M12: 2 | O12: =SUM(D12:N12) -> 8.5 | S12: =SUM(D12:G12,K12,M12) -> 5.5 | T12: =SUM(H12,I12,J12,L12) -> 3 | U12: =SUM(S12:T12) -> 8.5
A13: ='Mid Sem'!B13 -> 590029274 | B13: ='Mid Sem'!A13 -> Biswabandya Mohanty | C13: TRUE | D13: 1 | E13: 1 | F13: 1 | G13: 1 | H13: 0 | I13: 1 | J13: 1 | K13: 0 | L13: 2.5 | M13: 0 | O13: =SUM(D13:N13) -> 8.5 | S13: =SUM(D13:G13,K13,M13) -> 4 | T13: =SUM(H13,I13,J13,L13) -> 4.5 | U13: =SUM(S13:T13) -> 8.5
A14: ='Mid Sem'!B14 -> 590028572 | B14: ='Mid Sem'!A14 -> Eashan Vashisht | C14: TRUE | D14: 1 | E14: 1 | F14: 1 | G14: 1 | H14: 1 | I14: 1 | J14: 1 | K14: 2.5 | L14: 2.5 | M14: 0 | O14: =SUM(D14:N14) -> 12 | S14: =SUM(D14:G14,K14,M14) -> 6.5 | T14: =SUM(H14,I14,J14,L14) -> 5.5 | U14: =SUM(S14:T14) -> 12
A15: ='Mid Sem'!B15 -> 590029230 | B15: ='Mid Sem'!A15 -> Hardik Joshi | C15: FALSE | S15: =SUM(D15:G15,K15,M15) -> 0 | T15: =SUM(H15,I15,J15,L15) -> 0 | U15: =SUM(S15:T15) -> 0
A16: ='Mid Sem'!B16 -> 590029169 | B16: ='Mid Sem'!A16 -> Hrithvik Bhardwaj | C16: TRUE | D16: 1 | E16: 0 | F16: 1 | G16: 1 | H16: 1 | I16: 1 | J16: 1 | K16: 1 | L16: 1 | M16: 2.5 | O16: =SUM(D16:N16) -> 10.5 | S16: =SUM(D16:G16,K16,M16) -> 6.5 | T16: =SUM(H16,I16,J16,L16) -> 4 | U16: =SUM(S16:T16) -> 10.5
A17: ='Mid Sem'!B17 -> 590029112 | B17: ='Mid Sem'!A17 -> Nitish Kumar | C17: TRUE | D17: 1 | E17: 1 | F17: 1 | G17: 1 | H17: 1 | I17: 1 | J17: 1 | K17: 0.5 | L17: 1.5 | M17: 3 | O17: =SUM(D17:N17) -> 12 | S17: =SUM(D17:G17,K17,M17) -> 7.5 | T17: =SUM(H17,I17,J17,L17) -> 4.5 | U17: =SUM(S17:T17) -> 12
A18: ='Mid Sem'!B18 -> 590025556 | B18: ='Mid Sem'!A18 -> Omkareshwar Chaubey | C18: FALSE | S18: =SUM(D18:G18,K18,M18) -> 0 | T18: =SUM(H18,I18,J18,L18) -> 0 | U18: =SUM(S18:T18) -> 0
A19: ='Mid Sem'!B19 -> 590027830 | B19: ='Mid Sem'!A19 -> Pavani Jain | C19: FALSE | S19: =SUM(D19:G19,K19,M19) -> 0 | T19: =SUM(H19,I19,J19,L19) -> 0 | U19: =SUM(S19:T19) -> 0
A20: ='Mid Sem'!B20 -> 590028360 | B20: ='Mid Sem'!A20 -> Prapti Uniyal | C20: TRUE | D20: 1 | E20: 1 | F20: 1 | G20: 1 | H20: 0 | I20: 1 | J20: 0 | K20: 1.5 | L20: 2.5 | M20: 1 | O20: =SUM(D20:N20) -> 10 | S20: =SUM(D20:G20,K20,M20) -> 6.5 | T20: =SUM(H20,I20,J20,L20) -> 3.5 | U20: =SUM(S20:T20) -> 10
A21: ='Mid Sem'!B21 -> 590029237 | B21: ='Mid Sem'!A21 -> Priyadarshi Prabhakar | C21: TRUE | D21: 1 | E21: 0 | F21: 1 | G21: 1 | H21: 1 | I21: 1 | J21: 1 | K21: 0 | L21: 1 | M21: 1 | O21: =SUM(D21:N21) -> 8 | S21: =SUM(D21:G21,K21,M21) -> 4 | T21: =SUM(H21,I21,J21,L21) -> 4 | U21: =SUM(S21:T21) -> 8
A22: ='Mid Sem'!B22 -> 590029079 | B22: ='Mid Sem'!A22 -> Radhe Patel | C22: FALSE | S22: =SUM(D22:G22,K22,M22) -> 0 | T22: =SUM(H22,I22,J22,L22) -> 0 | U22: =SUM(S22:T22) -> 0
A23: ='Mid Sem'!B23 -> 590029145 | B23: ='Mid Sem'!A23 -> Rishika Purushotham | C23: TRUE | D23: 1 | E23: 1 | F23: 1 | G23: 1 | H23: 1 | I23: 1 | J23: 1 | K23: 2.5 | L23: 2.5 | M23: 3 | O23: =SUM(D23:N23) -> 15 | S23: =SUM(D23:G23,K23,M23) -> 9.5 | T23: =SUM(H23,I23,J23,L23) -> 5.5 | U23: =SUM(S23:T23) -> 15
A24: ='Mid Sem'!B24 -> 590029209 | B24: ='Mid Sem'!A24 -> Rishiv Kumar | C24: TRUE | D24: 1 | E24: 0 | F24: 1 | G24: 1 | H24: 1 | I24: 1 | J24: 1 | K24: 1 | L24: 1 | M24: 3 | O24: =SUM(D24:N24) -> 11 | S24: =SUM(D24:G24,K24,M24) -> 7 | T24: =SUM(H24,I24,J24,L24) -> 4 | U24: =SUM(S24:T24) -> 11
A25: ='Mid Sem'!B25 -> 590027268 | B25: ='Mid Sem'!A25 -> Sankalp Sunil Ronge | C25: TRUE | D25: 1 | E25: 1 | F25: 1 | G25: 1 | H25: 1 | I25: 1 | J25: 1 | K25: 1.5 | L25: 2.5 | M25: 0 | O25: =SUM(D25:N25) -> 11 | S25: =SUM(D25:G25,K25,M25) -> 5.5 | T25: =SUM(H25,I25,J25,L25) -> 5.5 | U25: =SUM(S25:T25) -> 11
A26: ='Mid Sem'!B26 -> 590029227 | B26: ='Mid Sem'!A26 -> Sartaj Singh | C26: TRUE | D26: 1 | E26: 1 | F26: 1 | G26: 1 | H26: 1 | I26: 1 | J26: 1 | K26: 2.5 | L26: 2.5 | M26: 3 | O26: =SUM(D26:N26) -> 15 | S26: =SUM(D26:G26,K26,M26) -> 9.5 | T26: =SUM(H26,I26,J26,L26) -> 5.5 | U26: =SUM(S26:T26) -> 15
A27: ='Mid Sem'!B27 -> 590029241 | B27: ='Mid Sem'!A27 -> Satakshi Gupta | C27: TRUE | D27: 1 | E27: 1 | F27: 1 | G27: 1 | H27: 1 | I27: 1 | J27: 1 | K27: 2 | L27: 2.5 | M27: 3 | O27: =SUM(D27:N27) -> 14.5 | S27: =SUM(D27:G27,K27,M27) -> 9 | T27: =SUM(H27,I27,J27,L27) -> 5.5 | U27: =SUM(S27:T27) -> 14.5
A28: ='Mid Sem'!B28 -> 590023855 | B28: ='Mid Sem'!A28 -> Shaswat Shantanu | C28: TRUE | D28: 1 | E28: 1 | F28: 1 | G28: 1 | H28: 1 | I28: 1 | J28: 1 | K28: 1 | L28: 2.5 | M28: 1.5 | O28: =SUM(D28:N28) -> 12 | S28: =SUM(D28:G28,K28,M28) -> 6.5 | T28: =SUM(H28,I28,J28,L28) -> 5.5 | U28: =SUM(S28:T28) -> 12
A29: ='Mid Sem'!B29 -> 590029215 | B29: ='Mid Sem'!A29 -> Siddhant Rai | C29: FALSE | S29: =SUM(D29:G29,K29,M29) -> 0 | T29: =SUM(H29,I29,J29,L29) -> 0 | U29: =SUM(S29:T29) -> 0
A30: ='Mid Sem'!B30 -> 590029111 | B30: ='Mid Sem'!A30 -> Sidhaant Singh Jyrwa | C30: TRUE | D30: 0 | E30: 1 | F30: 0 | G30: 1 | H30: 1 | I30: 1 | J30: 1 | K30: 0 | L30: 2.5 | M30: 1 | O30: =SUM(D30:N30) -> 8.5 | S30: =SUM(D30:G30,K30,M30) -> 3 | T30: =SUM(H30,I30,J30,L30) -> 5.5 | U30: =SUM(S30:T30) -> 8.5
A31: ='Mid Sem'!B31 -> 590028683 | B31: ='Mid Sem'!A31 -> Subrat Singh Jadaun | C31: TRUE | D31: 1 | E31: 1 | F31: 1 | G31: 1 | H31: 1 | I31: 1 | J31: 1 | K31: 2.5 | L31: 2.5 | M31: 0 | O31: =SUM(D31:N31) -> 12 | S31: =SUM(D31:G31,K31,M31) -> 6.5 | T31: =SUM(H31,I31,J31,L31) -> 5.5 | U31: =SUM(S31:T31) -> 12
A32: ='Mid Sem'!B32 -> 590029121 | B32: ='Mid Sem'!A32 -> Tushita Sharma | C32: TRUE | D32: 0 | E32: 1 | F32: 0 | G32: 1 | H32: 1 | I32: 1 | J32: 1 | K32: 0 | L32: 2.5 | M32: 1 | O32: =SUM(D32:N32) -> 8.5 | S32: =SUM(D32:G32,K32,M32) -> 3 | T32: =SUM(H32,I32,J32,L32) -> 5.5 | U32: =SUM(S32:T32) -> 8.5
A33: ='Mid Sem'!B33 -> 590029048 | B33: ='Mid Sem'!A33 -> Vaishnavi Kumari | C33: TRUE | D33: 1 | E33: 1 | F33: 1 | G33: 1 | H33: 1 | I33: 0 | J33: 1 | K33: 1 | L33: 1 | M33: 3 | O33: =SUM(D33:N33) -> 11 | S33: =SUM(D33:G33,K33,M33) -> 8 | T33: =SUM(H33,I33,J33,L33) -> 3 | U33: =SUM(S33:T33) -> 11
A34: ='Mid Sem'!B34 -> 590029184 | B34: ='Mid Sem'!A34 -> Vivek Chauhan | C34: TRUE | D34: 1 | E34: 1 | F34: 1 | G34: 1 | H34: 1 | I34: 1 | J34: 1 | K34: 2.5 | L34: 2.5 | M34: 3 | O34: =SUM(D34:N34) -> 15 | S34: =SUM(D34:G34,K34,M34) -> 9.5 | T34: =SUM(H34,I34,J34,L34) -> 5.5 | U34: =SUM(S34:T34) -> 15
A35: ='Mid Sem'!B35 -> 590029330 | B35: ='Mid Sem'!A35 -> Aadarshi Bisht | C35: TRUE | D35: 1 | E35: 1 | F35: 1 | G35: 1 | H35: 1 | I35: 1 | J35: 1 | K35: 2.5 | L35: 2.5 | M35: 0 | O35: =SUM(D35:N35) -> 12 | S35: =SUM(D35:G35,K35,M35) -> 6.5 | T35: =SUM(H35,I35,J35,L35) -> 5.5 | U35: =SUM(S35:T35) -> 12
A36: ='Mid Sem'!B36 -> 590027630 | B36: ='Mid Sem'!A36 -> Aarush Prasad | C36: TRUE | D36: 1 | E36: 1 | F36: 1 | G36: 1 | H36: 1 | I36: 1 | J36: 1 | K36: 2.5 | L36: 2.5 | M36: 3 | O36: =SUM(D36:N36) -> 15 | S36: =SUM(D36:G36,K36,M36) -> 9.5 | T36: =SUM(H36,I36,J36,L36) -> 5.5 | U36: =SUM(S36:T36) -> 15
A37: ='Mid Sem'!B37 -> 590029219 | B37: ='Mid Sem'!A37 -> Aditya Mishra | C37: TRUE | D37: 1 | E37: 1 | F37: 1 | G37: 1 | H37: 1 | I37: 1 | J37: 1 | K37: 0 | L37: 1 | M37: 0 | O37: =SUM(D37:N37) -> 8 | S37: =SUM(D37:G37,K37,M37) -> 4 | T37: =SUM(H37,I37,J37,L37) -> 4 | U37: =SUM(S37:T37) -> 8
A38: ='Mid Sem'!B38 -> 590028933 | B38: ='Mid Sem'!A38 -> Aman Barnwal | C38: TRUE | D38: 1 | E38: 1 | F38: 1 | G38: 1 | H38: 1 | I38: 1 | J38: 1 | K38: 2.5 | L38: 2.5 | M38: 3 | O38: =SUM(D38:N38) -> 15 | S38: =SUM(D38:G38,K38,M38) -> 9.5 | T38: =SUM(H38,I38,J38,L38) -> 5.5 | U38: =SUM(S38:T38) -> 15
A39: ='Mid Sem'!B39 -> 590027859 | B39: ='Mid Sem'!A39 -> Ashutosh Shrivastava | C39: TRUE | D39: 1 | E39: 1 | F39: 1 | G39: 1 | H39: 1 | I39: 1 | J39: 1 | K39: 1 | L39: 0 | M39: 0 | O39: =SUM(D39:N39) -> 8 | S39: =SUM(D39:G39,K39,M39) -> 5 | T39: =SUM(H39,I39,J39,L39) -> 3 | U39: =SUM(S39:T39) -> 8
A40: ='Mid Sem'!B40 -> 590028682 | B40: ='Mid Sem'!A40 -> Ayan Pande | C40: TRUE | D40: 1 | E40: 1 | F40: 1 | G40: 1 | H40: 1 | I40: 1 | J40: 1 | K40: 0 | L40: 2.5 | M40: 3 | O40: =SUM(D40:N40) -> 12.5 | S40: =SUM(D40:G40,K40,M40) -> 7 | T40: =SUM(H40,I40,J40,L40) -> 5.5 | U40: =SUM(S40:T40) -> 12.5
...

Sheet Class Test 1
A1: Class Test 1
A2: =Marksheet!A2 -> Physics for Computer Engineers (PHYS 1036)
D3: CO1 | E3: CO1 | F3: CO1 | G3: CO2 | H3: CO1 | I3: CO2 | T3: CO1 | U3: CO2
A4: Student Id | B4: Name | D4: Q1 | E4: Q2 | F4: Q3 | G4: Q4 | H4: Q5 | I4: Q6 | P4: Total | Q4: Sign | V4: Total
B5: Max Marks | D5: 2 | E5: 2 | F5: 2 | G5: 2 | H5: 6 | I5: 6 | P5: =SUM(D5:M5) -> 20 | T5: =SUM(D5,E5,F5,H5) -> 12 | U5: =SUM(G5,I5) -> 8 | V5: =SUM(T5:U5) -> 20
A6: =Marksheet!B5 -> 590029213 | B6: =Marksheet!A5 -> Aadya Dubey | C6: TRUE | D6: 2 | E6: 2 | F6: 2 | G6: 2 | H6: 6 | I6: 6 | P6: =SUM(D6:M6) -> 20 | T6: =SUM(D6,E6,F6,H6) -> 12 | U6: =SUM(G6,I6) -> 8 | V6: =SUM(T6:U6) -> 20
A7: =Marksheet!B6 -> 590029270 | B7: =Marksheet!A6 -> Aditya Vishwakarma | C7: TRUE | D7: 0.5 | E7: 1.5 | F7: 2 | G7: 1 | H7: 3 | I7: 4 | P7: =SUM(D7:M7) -> 12 | T7: =SUM(D7,E7,F7,H7) -> 7 | U7: =SUM(G7,I7) -> 5 | V7: =SUM(T7:U7) -> 12
A8: =Marksheet!B7 -> 590029204 | B8: =Marksheet!A7 -> Arjun | C8: TRUE | D8: 2 | E8: 1 | F8: 1 | G8: 0 | H8: 2 | I8: 1 | P8: =SUM(D8:M8) -> 7 | T8: =SUM(D8,E8,F8,H8) -> 6 | U8: =SUM(G8,I8) -> 1 | V8: =SUM(T8:U8) -> 7
A9: =Marksheet!B8 -> 590029109 | B9: =Marksheet!A8 -> Aryan Yadav | C9: TRUE | D9: 1 | E9: 1.5 | F9: 1.5 | G9: 2 | H9: 4 | I9: 5 | P9: =SUM(D9:M9) -> 15 | T9: =SUM(D9,E9,F9,H9) -> 8 | U9: =SUM(G9,I9) -> 7 | V9: =SUM(T9:U9) -> 15
A10: =Marksheet!B9 -> 590029070 | B10: =Marksheet!A9 -> Astik Patel | C10: TRUE | D10: 2 | E10: 2 | F10: 2 | G10: 2 | H10: 6 | I10: 2 | P10: =SUM(D10:M10) -> 16 | T10: =SUM(D10,E10,F10,H10) -> 12 | U10: =SUM(G10,I10) -> 4 | V10: =SUM(T10:U10) -> 16
A11: =Marksheet!B10 -> 590029157 | B11: =Marksheet!A10 -> Ayush Mohan | C11: TRUE | D11: 1.5 | E11: 0.5 | F11: 2 | G11: 2 | H11: 1 | I11: 5 | P11: =SUM(D11:M11) -> 12 | T11: =SUM(D11,E11,F11,H11) -> 5 | U11: =SUM(G11,I11) -> 7 | V11: =SUM(T11:U11) -> 12
A12: =Marksheet!B11 -> 590027157 | B12: =Marksheet!A11 -> Bhanu Purohit | C12: TRUE | D12: 2 | E12: 1 | F12: 2 | G12: 2 | H12: 1 | I12: 6 | P12: =SUM(D12:M12) -> 14 | T12: =SUM(D12,E12,F12,H12) -> 6 | U12: =SUM(G12,I12) -> 8 | V12: =SUM(T12:U12) -> 14
A13: =Marksheet!B12 -> 590029274 | B13: =Marksheet!A12 -> Biswabandya Mohanty | C13: TRUE | D13: 2 | E13: 2 | F13: 2 | G13: 2 | H13: 6 | I13: 5 | P13: =SUM(D13:M13) -> 19 | T13: =SUM(D13,E13,F13,H13) -> 12 | U13: =SUM(G13,I13) -> 7 | V13: =SUM(T13:U13) -> 19
A14: =Marksheet!B13 -> 590028572 | B14: =Marksheet!A13 -> Eashan Vashisht | C14: TRUE | D14: 2 | E14: 2 | F14: 2 | G14: 2 | H14: 6 | I14: 6 | P14: =SUM(D14:M14) -> 20 | T14: =SUM(D14,E14,F14,H14) -> 12 | U14: =SUM(G14,I14) -> 8 | V14: =SUM(T14:U14) -> 20
A15: =Marksheet!B14 -> 590029230 | B15: =Marksheet!A14 -> Hardik Joshi | C15: FALSE | P15: =SUM(D15:M15) -> 0 | T15: =SUM(D15,E15,F15,H15) -> 0 | U15: =SUM(G15,I15) -> 0 | V15: =SUM(T15:U15) -> 0
A16: =Marksheet!B15 -> 590029169 | B16: =Marksheet!A15 -> Hrithvik Bhardwaj | C16: TRUE | D16: 2 | E16: 1.5 | F16: 1.5 | G16: 0 | H16: 0 | I16: 4 | P16: =SUM(D16:M16) -> 9 | T16: =SUM(D16,E16,F16,H16) -> 5 | U16: =SUM(G16,I16) -> 4 | V16: =SUM(T16:U16) -> 9
A17: =Marksheet!B16 -> 590029112 | B17: =Marksheet!A16 -> Nitish Kumar | C17: TRUE | D17: 1 | E17: 1.5 | F17: 2 | G17: 1.5 | H17: 4 | I17: 5 | P17: =SUM(D17:M17) -> 15 | T17: =SUM(D17,E17,F17,H17) -> 8.5 | U17: =SUM(G17,I17) -> 6.5 | V17: =SUM(T17:U17) -> 15
A18: =Marksheet!B17 -> 590025556 | B18: =Marksheet!A17 -> Omkareshwar Chaubey | C18: TRUE | D18: 2 | E18: 2 | F18: 2 | G18: 2 | H18: 6 | I18: 5 | P18: =SUM(D18:M18) -> 19 | T18: =SUM(D18,E18,F18,H18) -> 12 | U18: =SUM(G18,I18) -> 7 | V18: =SUM(T18:U18) -> 19
A19: =Marksheet!B18 -> 590027830 | B19: =Marksheet!A18 -> Pavani Jain | C19: TRUE | D19: 2 | E19: 1.5 | F19: 2 | G19: 2 | H19: 6 | I19: 5 | P19: =SUM(D19:M19) -> 18.5 | T19: =SUM(D19,E19,F19,H19) -> 11.5 | U19: =SUM(G19,I19) -> 7 | V19: =SUM(T19:U19) -> 18.5
A20: =Marksheet!B19 -> 590028360 | B20: =Marksheet!A19 -> Prapti Uniyal | C20: TRUE | D20: 2 | E20: 1 | F20: 2 | G20: 1.5 | H20: 5 | I20: 0 | P20: =SUM(D20:M20) -> 11.5 | T20: =SUM(D20,E20,F20,H20) -> 10 | U20: =SUM(G20,I20) -> 1.5 | V20: =SUM(T20:U20) -> 11.5
A21: =Marksheet!B20 -> 590029237 | B21: =Marksheet!A20 -> Priyadarshi Prabhakar | C21: TRUE | D21: 1.5 | E21: 1 | F21: 1 | G21: 2 | H21: 1 | I21: 4 | P21: =SUM(D21:M21) -> 10.5 | T21: =SUM(D21,E21,F21,H21) -> 4.5 | U21: =SUM(G21,I21) -> 6 | V21: =SUM(T21:U21) -> 10.5
A22: =Marksheet!B21 -> 590029079 | B22: =Marksheet!A21 -> Radhe Patel | C22: FALSE | P22: =SUM(D22:M22) -> 0 | T22: =SUM(D22,E22,F22,H22) -> 0 | U22: =SUM(G22,I22) -> 0 | V22: =SUM(T22:U22) -> 0
A23: =Marksheet!B22 -> 590029145 | B23: =Marksheet!A22 -> Rishika Purushotham | C23: TRUE | D23: 2 | E23: 2 | F23: 2 | G23: 2 | H23: 5 | I23: 6 | P23: =SUM(D23:M23) -> 19 | T23: =SUM(D23,E23,F23,H23) -> 11 | U23: =SUM(G23,I23) -> 8 | V23: =SUM(T23:U23) -> 19
A24: =Marksheet!B23 -> 590029209 | B24: =Marksheet!A23 -> Rishiv Kumar | C24: FALSE | P24: =SUM(D24:M24) -> 0 | T24: =SUM(D24,E24,F24,H24) -> 0 | U24: =SUM(G24,I24) -> 0 | V24: =SUM(T24:U24) -> 0
A25: =Marksheet!B24 -> 590027268 | B25: =Marksheet!A24 -> Sankalp Sunil Ronge | C25: TRUE | D25: 2 | E25: 1.5 | F25: 2 | G25: 1 | H25: 2 | I25: 4 | P25: =SUM(D25:M25) -> 12.5 | T25: =SUM(D25,E25,F25,H25) -> 7.5 | U25: =SUM(G25,I25) -> 5 | V25: =SUM(T25:U25) -> 12.5
A26: =Marksheet!B25 -> 590029227 | B26: =Marksheet!A25 -> Sartaj Singh | C26: TRUE | D26: 2 | E26: 1.5 | F26: 2 | G26: 2 | H26: 6 | I26: 6 | P26: =SUM(D26:M26) -> 19.5 | T26: =SUM(D26,E26,F26,H26) -> 11.5 | U26: =SUM(G26,I26) -> 8 | V26: =SUM(T26:U26) -> 19.5
A27: =Marksheet!B26 -> 590029241 | B27: =Marksheet!A26 -> Satakshi Gupta | C27: TRUE | D27: 1.5 | E27: 1.5 | F27: 2 | G27: 2 | H27: 2 | I27: 2 | P27: =SUM(D27:M27) -> 11 | T27: =SUM(D27,E27,F27,H27) -> 7 | U27: =SUM(G27,I27) -> 4 | V27: =SUM(T27:U27) -> 11
A28: =Marksheet!B27 -> 590023855 | B28: =Marksheet!A27 -> Shaswat Shantanu | C28: TRUE | D28: 1.5 | E28: 1 | F28: 2 | G28: 2 | H28: 3 | I28: 2 | P28: =SUM(D28:M28) -> 11.5 | T28: =SUM(D28,E28,F28,H28) -> 7.5 | U28: =SUM(G28,I28) -> 4 | V28: =SUM(T28:U28) -> 11.5
A29: =Marksheet!B28 -> 590029215 | B29: =Marksheet!A28 -> Siddhant Rai | C29: TRUE | D29: 2 | E29: 0.5 | F29: 2 | G29: 0 | H29: 2 | I29: 0 | P29: =SUM(D29:M29) -> 6.5 | T29: =SUM(D29,E29,F29,H29) -> 6.5 | U29: =SUM(G29,I29) -> 0 | V29: =SUM(T29:U29) -> 6.5
A30: =Marksheet!B29 -> 590029111 | B30: =Marksheet!A29 -> Sidhaant Singh Jyrwa | C30: TRUE | D30: 1 | E30: 1 | F30: 0 | G30: 0 | H30: 0 | I30: 0 | P30: =SUM(D30:M30) -> 2 | T30: =SUM(D30,E30,F30,H30) -> 2 | U30: =SUM(G30,I30) -> 0 | V30: =SUM(T30:U30) -> 2
A31: =Marksheet!B30 -> 590028683 | B31: =Marksheet!A30 -> Subrat Singh Jadaun | C31: TRUE | D31: 1 | E31: 1 | F31: 2 | G31: 1 | H31: 2 | I31: 2 | P31: =SUM(D31:M31) -> 9 | T31: =SUM(D31,E31,F31,H31) -> 6 | U31: =SUM(G31,I31) -> 3 | V31: =SUM(T31:U31) -> 9
A32: =Marksheet!B31 -> 590029121 | B32: =Marksheet!A31 -> Tushita Sharma | C32: TRUE | D32: 2 | E32: 1.5 | F32: 2 | G32: 2 | H32: 4 | I32: 6 | P32: =SUM(D32:M32) -> 17.5 | T32: =SUM(D32,E32,F32,H32) -> 9.5 | U32: =SUM(G32,I32) -> 8 | V32: =SUM(T32:U32) -> 17.5
A33: =Marksheet!B32 -> 590029048 | B33: =Marksheet!A32 -> Vaishnavi Kumari | C33: TRUE | D33: 2 | E33: 2 | F33: 2 | G33: 2 | H33: 6 | I33: 6 | P33: =SUM(D33:M33) -> 20 | T33: =SUM(D33,E33,F33,H33) -> 12 | U33: =SUM(G33,I33) -> 8 | V33: =SUM(T33:U33) -> 20
A34: =Marksheet!B33 -> 590029184 | B34: =Marksheet!A33 -> Vivek Chauhan | C34: TRUE | D34: 2 | E34: 2 | F34: 1.5 | G34: 2 | H34: 6 | I34: 6 | P34: =SUM(D34:M34) -> 19.5 | T34: =SUM(D34,E34,F34,H34) -> 11.5 | U34: =SUM(G34,I34) -> 8 | V34: =SUM(T34:U34) -> 19.5
A35: =Marksheet!B34 -> 590029330 | B35: =Marksheet!A34 -> Aadarshi Bisht | C35: TRUE | D35: 1.5 | E35: 1.5 | F35: 2 | G35: 2 | H35: 2 | I35: 4 | P35: =SUM(D35:M35) -> 13 | T35: =SUM(D35,E35,F35,H35) -> 7 | U35: =SUM(G35,I35) -> 6 | V35: =SUM(T35:U35) -> 13
A36: =Marksheet!B35 -> 590027630 | B36: =Marksheet!A35 -> Aarush Prasad | C36: TRUE | D36: 2 | E36: 2 | F36: 2 | G36: 2 | H36: 3 | I36: 6 | P36: =SUM(D36:M36) -> 17 | T36: =SUM(D36,E36,F36,H36) -> 9 | U36: =SUM(G36,I36) -> 8 | V36: =SUM(T36:U36) -> 17
... A42: =Marksheet!B41 -> 590023785 | B42: =Marksheet!A41 -> Gayatri Bhatt | C42: TRUE | D42: 1 | E42: 1 | F42: 2 | G42: 2 | H42: 3 | I42: 6 | P42: =SUM(D42:M42) -> 15 | T42: =SUM(D42,E42,F42,H42) -> 7 | U42: =SUM(G42,I42) -> 8 | V42: =SUM(T42:U42) -> 15
A43: =Marksheet!B42 -> 590029264 | B43: =Marksheet!A42 -> Harsh Mudgal | C43: FALSE | P43: =SUM(D43:M43) -> 0 | T43: =SUM(D43,E43,F43,H43) -> 0 | U43: =SUM(G43,I43) -> 0 | V43: =SUM(T43:U43) -> 0
A44: =Marksheet!B43 -> 590029042 | B44: =Marksheet!A43 -> Kanan Nidhania | C44: FALSE | P44: =SUM(D44:M44) -> 0 | T44: =SUM(D44,E44,F44,H44) -> 0 | U44: =SUM(G44,I44) -> 0 | V44: =SUM(T44:U44) -> 0
A45: =Marksheet!B44 -> 590029336 | B45: =Marksheet!A44 -> Kanishka Diwakar | C45: TRUE | D45: 1.5 | E45: 1.5 | F45: 2 | G45: 2 | H45: 4 | I45: 4 | P45: =SUM(D45:M45) -> 15 | T45: =SUM(D45,E45,F45,H45) -> 9 | U45: =SUM(G45,I45) -> 6 | V45: =SUM(T45:U45) -> 15
...

Sheet Mid Sem
A1: Mid Sem Examination
A2: =Marksheet!A2 -> Physics for Computer Engineers (PHYS 1036)
D3: CO1 | E3: CO1 | F3: CO1 | G3: CO2 | H3: CO1 | I3: CO1 | J3: CO1 | K3: CO2 | L3: CO2/CO1 | S3: CO1 | T3: CO2
A4: Name | B4: Student ID | C4: Batch | D4: Q1 | E4: Q2 | F4: Q3 | G4: Q4 | H4: Q5 | I4: Q6 | J4: Q7 | K4: Q8 | L4: Q9 | M4: Q10 | N4: Q11 | O4: Total | P4: Sign | U4: Total
B5: Max Marks | D5: 6 | E5: 6 | F5: 6 | G5: 6 | H5: 6 | I5: 15 | J5: 15 | K5: 15 | L5: 25 | O5: =SUM(D5:L5) -> 100 | S5: =SUM(D5:F5,H5,I5,J5,L5/5) -> 59 | T5: =SUM(G5,K5,L5*4/5) -> 41 | U5: =SUM(S5:T5) -> 100
A6: =Marksheet!A5 -> Aadya Dubey | B6: =Marksheet!B5 -> 590029213 | C6: 77 | D6: 6 | E6: 6 | F6: 5 | G6: 6 | H6: 6 | I6: 15 | J6: 12 | K6: 5 | L6: 25 | O6: =SUM(D6:L6) -> 86 | S6: =SUM(D6:F6,H6,I6,J6,L6/5) -> 55 | T6: =SUM(G6,K6,L6*4/5) -> 31 | U6: =SUM(S6:T6) -> 86
A7: =Marksheet!A6 -> Aditya Vishwakarma | B7: =Marksheet!B6 -> 590029270 | C7: 77 | D7: 2 | E7: 1 | F7: 4 | J7: 10 | K7: 5 | L7: 10 | O7: =SUM(D7:L7) -> 32 | S7: =SUM(D7:F7,H7,I7,J7,L7/5) -> 19 | T7: =SUM(G7,K7,L7*4/5) -> 13 | U7: =SUM(S7:T7) -> 32
A8: =Marksheet!A7 -> Arjun | B8: =Marksheet!B7 -> 590029204 | C8: 77 | D8: 2 | E8: 4 | F8: 6 | G8: 1 | I8: 8 | L8: 8 | O8: =SUM(D8:L8) -> 29 | S8: =SUM(D8:F8,H8,I8,J8,L8/5) -> 21.6 | T8: =SUM(G8,K8,L8*4/5) -> 7.4 | U8: =SUM(S8:T8) -> 29
A9: =Marksheet!A8 -> Aryan Yadav | B9: =Marksheet!B8 -> 590029109 | C9: 77 | D9: 6 | E9: 3 | F9: 2 | H9: 3 | I9: 6 | J9: 11 | K9: 5 | L9: 2 | O9: =SUM(D9:L9) -> 38 | S9: =SUM(D9:F9,H9,I9,J9,L9/5) -> 31.4 | T9: =SUM(G9,K9,L9*4/5) -> 6.6 | U9: =SUM(S9:T9) -> 38
A10: =Marksheet!A9 -> Astik Patel | B10: =Marksheet!B9 -> 590029070 | C10: 77 | D10: 6 | E10: 4 | F10: 3 | G10: 6 | H10: 6 | I10: 10 | J10: 15 | K10: 15 | L10: 25 | O10: =SUM(D10:L10) -> 90 | S10: =SUM(D10:F10,H10,I10,J10,L10/5) -> 49 | T10: =SUM(G10,K10,L10*4/5) -> 41 | U10: =SUM(S10:T10) -> 90
A11: =Marksheet!A10 -> Ayush Mohan | B11: =Marksheet!B10 -> 590029157 | C11: 77 | D11: 3 | E11: 4 | F11: 1 | J11: 6 | O11: =SUM(D11:L11) -> 14 | S11: =SUM(D11:F11,H11,I11,J11,L11/5) -> 14 | T11: =SUM(G11,K11,L11*4/5) -> 0 | U11: =SUM(S11:T11) -> 14
A12: =Marksheet!A11 -> Bhanu Purohit | B12: =Marksheet!B11 -> 590027157 | C12: 77 | D12: 5 | E12: 6 | F12: 3 | G12: 1 | H12: 2 | I12: 6 | J12: 12 | K12: 8 | L12: 7 | O12: =SUM(D12:L12) -> 50 | S12: =SUM(D12:F12,H12,I12,J12,L12/5) -> 35.4 | T12: =SUM(G12,K12,L12*4/5) -> 14.6 | U12: =SUM(S12:T12) -> 50
A13: =Marksheet!A12 -> Biswabandya Mohanty | B13: =Marksheet!B12 -> 590029274 | C13: 77 | D13: 4 | I13: 4 | O13: =SUM(D13:L13) -> 8 | S13: =SUM(D13:F13,H13,I13,J13,L13/5) -> 8 | T13: =SUM(G13,K13,L13*4/5) -> 0 | U13: =SUM(S13:T13) -> 8
A14: =Marksheet!A13 -> Eashan Vashisht | B14: =Marksheet!B13 -> 590028572 | C14: 77 | D14: 6 | E14: 6 | F14: 6 | G14: 1 | H14: 0 | I14: 7 | J14: 15 | K14: 8 | L14: 5 | O14: =SUM(D14:L14) -> 54 | S14: =SUM(D14:F14,H14,I14,J14,L14/5) -> 41 | T14: =SUM(G14,K14,L14*4/5) -> 13 | U14: =SUM(S14:T14) -> 54
A15: =Marksheet!A14 -> Hardik Joshi | B15: =Marksheet!B14 -> 590029230 | C15: 77 | O15: =SUM(D15:L15) -> 0 | S15: =SUM(D15:F15,H15,I15,J15,L15/5) -> 0 | T15: =SUM(G15,K15,L15*4/5) -> 0 | U15: =SUM(S15:T15) -> 0
A16: =Marksheet!A15 -> Hrithvik Bhardwaj | B16: =Marksheet!B15 -> 590029169 | C16: 77 | D16: 1 | O16: =SUM(D16:L16) -> 1 | S16: =SUM(D16:F16,H16,I16,J16,L16/5) -> 1 | T16: =SUM(G16,K16,L16*4/5) -> 0 | U16: =SUM(S16:T16) -> 1
A17: =Marksheet!A16 -> Nitish Kumar | B17: =Marksheet!B16 -> 590029112 | C17: 77 | D17: 6 | E17: 3 | F17: 4 | H17: 2 | I17: 5 | J17: 8 | L17: 7 | O17: =SUM(D17:L17) -> 35 | S17: =SUM(D17:F17,H17,I17,J17,L17/5) -> 29.4 | T17: =SUM(G17,K17,L17*4/5) -> 5.6 | U17: =SUM(S17:T17) -> 35
A18: =Marksheet!A17 -> Omkareshwar Chaubey | B18: =Marksheet!B17 -> 590025556 | C18: 77 | D18: 4 | E18: 6 | F18: 3 | G18: 2 | H18: 3 | I18: 8 | J18: 3 | K18: 15 | L18: 13 | O18: =SUM(D18:L18) -> 57 | S18: =SUM(D18:F18,H18,I18,J18,L18/5) -> 29.6 | T18: =SUM(G18,K18,L18*4/5) -> 27.4 | U18: =SUM(S18:T18) -> 57
A19: =Marksheet!A18 -> Pavani Jain | B19: =Marksheet!B18 -> 590027830 | C19: 77 | D19: 6 | E19: 6 | F19: 6 | G19: 6 | H19: 6 | I19: 15 | J19: 14 | K19: 15 | L19: 24 | O19: =SUM(D19:L19) -> 98 | S19: =SUM(D19:F19,H19,I19,J19,L19/5) -> 57.8 | T19: =SUM(G19,K19,L19*4/5) -> 40.2 | U19: =SUM(S19:T19) -> 98
A20: =Marksheet!A19 -> Prapti Uniyal | B20: =Marksheet!B19 -> 590028360 | C20: 77 | D20: 4 | E20: 6 | F20: 4 | G20: 5 | H20: 4 | I20: 15 | J20: 5 | K20: 0 | L20: 8 | O20: =SUM(D20:L20) -> 51 | S20: =SUM(D20:F20,H20,I20,J20,L20/5) -> 39.6 | T20: =SUM(G20,K20,L20*4/5) -> 11.4 | U20: =SUM(S20:T20) -> 51
A21: =Marksheet!A20 -> Priyadarshi Prabhakar | B21: =Marksheet!B20 -> 590029237 | C21: 77 | D21: 2 | E21: 4 | F21: 3 | I21: 3 | J21: 12 | L21: 5 | O21: =SUM(D21:L21) -> 29 | S21: =SUM(D21:F21,H21,I21,J21,L21/5) -> 25 | T21: =SUM(G21,K21,L21*4/5) -> 4 | U21: =SUM(S21:T21) -> 29
A22: =Marksheet!A21 -> Radhe Patel | B22: =Marksheet!B21 -> 590029079 | C22: 77 | D22: 1 | E22: 0 | F22: 0 | G22: 0 | H22: 0 | I22: 0 | J22: 0 | K22: 0 | L22: 0 | O22: =SUM(D22:L22) -> 1 | S22: =SUM(D22:F22,H22,I22,J22,L22/5) -> 1 | T22: =SUM(G22,K22,L22*4/5) -> 0 | U22: =SUM(S22:T22) -> 1
A23: =Marksheet!A22 -> Rishika Purushotham | B23: =Marksheet!B22 -> 590029145 | C23: 77 | D23: 4 | E23: 2 | F23: 5 | G23: 4 | H23: 4 | I23: 2 | J23: 2 | O23: =SUM(D23:L23) -> 23 | S23: =SUM(D23:F23,H23,I23,J23,L23/5) -> 19 | T23: =SUM(G23,K23,L23*4/5) -> 4 | U23: =SUM(S23:T23) -> 23
A24: =Marksheet!A23 -> Rishiv Kumar | B24: =Marksheet!B23 -> 590029209 | C24: 77 | D24: 4 | F24: 2 | K24: 3 | L24: 8 | O24: =SUM(D24:L24) -> 17 | S24: =SUM(D24:F24,H24,I24,J24,L24/5) -> 7.6 | T24: =SUM(G24,K24,L24*4/5) -> 9.4 | U24: =SUM(S24:T24) -> 17
A25: =Marksheet!A24 -> Sankalp Sunil Ronge | B25: =Marksheet!B24 -> 590027268 | C25: 77 | D25: 6 | E25: 1 | K25: 1 | O25: =SUM(D25:L25) -> 8 | S25: =SUM(D25:F25,H25,I25,J25,L25/5) -> 7 | T25: =SUM(G25,K25,L25*4/5) -> 1 | U25: =SUM(S25:T25) -> 8
A26: =Marksheet!A25 -> Sartaj Singh | B26: =Marksheet!B25 -> 590029227 | C26: 77 | D26: 6 | E26: 6 | F26: 6 | G26: 6 | H26: 6 | I26: 15 | J26: 15 | K26: 7 | L26: 18 | O26: =SUM(D26:L26) -> 85 | S26: =SUM(D26:F26,H26,I26,J26,L26/5) -> 57.6 | T26: =SUM(G26,K26,L26*4/5) -> 27.4 | U26: =SUM(S26:T26) -> 85
A27: =Marksheet!A26 -> Satakshi Gupta | B27: =Marksheet!B26 -> 590029241 | C27: 77 | D27: 2 | E27: 4 | F27: 6 | I27: 15 | J27: 14 | K27: 2 | O27: =SUM(D27:L27) -> 43 | S27: =SUM(D27:F27,H27,I27,J27,L27/5) -> 41 | T27: =SUM(G27,K27,L27*4/5) -> 2 | U27: =SUM(S27:T27) -> 43
A28: =Marksheet!A27 -> Shaswat Shantanu | B28: =Marksheet!B27 -> 590023855 | C28: 77 | D28: 4 | I28: 5 | J28: 11 | L28: 9 | O28: =SUM(D28:L28) -> 29 | S28: =SUM(D28:F28,H28,I28,J28,L28/5) -> 21.8 | T28: =SUM(G28,K28,L28*4/5) -> 7.2 | U28: =SUM(S28:T28) -> 29
A29: =Marksheet!A28 -> Siddhant Rai | B29: =Marksheet!B28 -> 590029215 | C29: 77 | D29: 6 | E29: 5 | F29: 3 | I29: 7 | O29: =SUM(D29:L29) -> 21 | S29: =SUM(D29:F29,H29,I29,J29,L29/5) -> 21 | T29: =SUM(G29,K29,L29*4/5) -> 0 | U29: =SUM(S29:T29) -> 21
A30: =Marksheet!A29 -> Sidhaant Singh Jyrwa | B30: =Marksheet!B29 -> 590029111 | C30: 77 | D30: 2 | F30: 1 | O30: =SUM(D30:L30) -> 3 | S30: =SUM(D30:F30,H30,I30,J30,L30/5) -> 3 | T30: =SUM(G30,K30,L30*4/5) -> 0 | U30: =SUM(S30:T30) -> 3
A31: =Marksheet!A30 -> Subrat Singh Jadaun | B31: =Marksheet!B30 -> 590028683 | C31: 77 | D31: 6 | E31: 3 | F31: 3 | G31: 2 | I31: 5 | J31: 4 | O31: =SUM(D31:L31) -> 23 | S31: =SUM(D31:F31,H31,I31,J31,L31/5) -> 21 | T31: =SUM(G31,K31,L31*4/5) -> 2 | U31: =SUM(S31:T31) -> 23
A32: =Marksheet!A31 -> Tushita Sharma | B32: =Marksheet!B31 -> 590029121 | C32: 77 | D32: 6 | E32: 6 | F32: 6 | G32: 4 | H32: 5 | I32: 15 | J32: 8 | K32: 5 | L32: 24 | O32: =SUM(D32:L32) -> 79 | S32: =SUM(D32:F32,H32,I32,J32,L32/5) -> 50.8 | T32: =SUM(G32,K32,L32*4/5) -> 28.2 | U32: =SUM(S32:T32) -> 79
A33: =Marksheet!A32 -> Vaishnavi Kumari | B33: =Marksheet!B32 -> 590029048 | C33: 77 | D33: 6 | E33: 5 | F33: 5 | H33: 2 | I33: 8 | O33: =SUM(D33:L33) -> 26 | S33: =SUM(D33:F33,H33,I33,J33,L33/5) -> 26 | T33: =SUM(G33,K33,L33*4/5) -> 0 | U33: =SUM(S33:T33) -> 26
A34: =Marksheet!A33 -> Vivek Chauhan | B34: =Marksheet!B33 -> 590029184 | C34: 77 | D34: 6 | E34: 6 | F34: 3 | G34: 1 | H34: 2 | I34: 12 | J34: 15 | K34: 15 | L34: 5 | O34: =SUM(D34:L34) -> 65 | S34: =SUM(D34:F34,H34,I34,J34,L34/5) -> 45 | T34: =SUM(G34,K34,L34*4/5) -> 20 | U34: =SUM(S34:T34) -> 65
A35: =Marksheet!A34 -> Aadarshi Bisht | B35: =Marksheet!B34 -> 590029330 | C35: 78 | D35: 3 | E35: 6 | F35: 5 | G35: 0 | H35: 4 | I35: 5 | J35: 13 | K35: 0 | L35: 2 | O35: =SUM(D35:L35) -> 38 | S35: =SUM(D35:F35,H35,I35,J35,L35/5) -> 36.4 | T35: =SUM(G35,K35,L35*4/5) -> 1.6 | U35: =SUM(S35:T35) -> 38
A36: =Marksheet!A35 -> Aarush Prasad | B36: =Marksheet!B35 -> 590027630 | C36: 78 | D36: 0 | E36: 0 | F36: 0 | G36: 0 | H36: 0 | I36: 0 | J36: 0 | K36: 0 | L36: 0 | O36: =SUM(D36:L36) -> 0 | S36: =SUM(D36:F36,H36,I36,J36,L36/5) -> 0 | T36: =SUM(G36,K36,L36*4/5) -> 0 | U36: =SUM(S36:T36) -> 0
A37: =Marksheet!A36 -> Aditya Mishra | B37: =Marksheet!B36 -> 590029219 | C37: 78 | D37: 6 | E37: 4 | F37: 5 | G37: 0 | H37: 0 | I37: 13 | J37: 3 | K37: 0 | L37: 0 | O37: =SUM(D37:L37) -> 31 | S37: =SUM(D37:F37,H37,I37,J37,L37/5) -> 31 | T37: =SUM(G37,K37,L37*4/5) -> 0 | U37: =SUM(S37:T37) -> 31
A38: =Marksheet!A37 -> Aman Barnwal | B38: =Marksheet!B37 -> 590028933 | C38: 78 | D38: 4 | E38: 6 | F38: 5 | G38: 2 | H38: 5 | I38: 15 | J38: 12 | K38: 2 | L38: 5 | O38: =SUM(D38:L38) -> 56 | S38: =SUM(D38:F38,H38,I38,J38,L38/5) -> 48 | T38: =SUM(G38,K38,L38*4/5) -> 8 | U38: =SUM(S38:T38) -> 56
A39: =Marksheet!A38 -> Ashutosh Shrivastava | B39: =Marksheet!B38 -> 590027859 | C39: 78 | D39: 2 | E39: 0 | F39: 0 | G39: 0 | H39: 0 | I39: 0 | J39: 0 | K39: 0 | L39: 0 | O39: =SUM(D39:L39) -> 2 | S39: =SUM(D39:F39,H39,I39,J39,L39/5) -> 2 | T39: =SUM(G39,K39,L39*4/5) -> 0 | U39: =SUM(S39:T39) -> 2
A40: =Marksheet!A39 -> Ayan Pande | B40: =Marksheet!B39 -> 590028682 | C40: 78 | D40: 6 | E40: 6 | F40: 5 | G40: 6 | H40: 6 | I40: 13 | J40: 5 | K40: 5 | L40: 2 | O40: =SUM(D40:L40) -> 54 | S40: =SUM(D40:F40,H40,I40,J40,L40/5) -> 41.4 | T40: =SUM(G40,K40,L40*4/5) -> 12.6 | U40: =SUM(S40:T40) -> 54
...

Sheet End Sem
A1: End Sem Examination
A2: =Marksheet!A2 -> Physics for Computer Engineers (PHYS 1036)
C3: CO1 | D3: CO2 | E3: CO3 | F3: CO1 | G3: CO2 | H3: CO1 | I3: CO3 | J3: CO3 | K3: CO4 | L3: CO3 | M3: CO4
A4: Student Id | B4: Name | C4: Q1 | D4: Q2 | E4: Q3 | F4: Q4 | G4: Q5 | H4: Q6 | I4: Q7 | J4: Q8 | K4: Q9 | L4: Q10 | M4: Q11 | N4: Total | O4: Sign
B5: Max Marks | C5: 4 | D5: 4 | E5: 4 | F5: 4 | G5: 4 | H5: 10 | I5: 10 | J5: 10 | K5: 10 | L5: 20 | M5: 20 | N5: =SUM(C5:M5) -> 100
A6: ='Mid Sem'!B6 -> 590029213 | B6: ='Mid Sem'!A6 -> Aadya Dubey
A7: ='Mid Sem'!B7 -> 590029270 | B7: ='Mid Sem'!A7 -> Aditya Vishwakarma
A8: ='Mid Sem'!B8 -> 590029204 | B8: ='Mid Sem'!A8 -> Arjun
A9: ='Mid Sem'!B9 -> 590029109 | B9: ='Mid Sem'!A9 -> Aryan Yadav
A10: ='Mid Sem'!B10 -> 590029070 | B10: ='Mid Sem'!A10 -> Astik Patel
A11: ='Mid Sem'!B11 -> 590029157 | B11: ='Mid Sem'!A11 -> Ayush Mohan
A12: ='Mid Sem'!B12 -> 590027157 | B12: ='Mid Sem'!A12 -> Bhanu Purohit
A13: ='Mid Sem'!B13 -> 590029274 | B13: ='Mid Sem'!A13 -> Biswabandya Mohanty
A14: ='Mid Sem'!B14 -> 590028572 | B14: ='Mid Sem'!A14 -> Eashan Vashisht
A15: ='Mid Sem'!B15 -> 590029230 | B15: ='Mid Sem'!A15 -> Hardik Joshi
A16: ='Mid Sem'!B16 -> 590029169 | B16: ='Mid Sem'!A16 -> Hrithvik Bhardwaj
A17: ='Mid Sem'!B17 -> 590029112 | B17: ='Mid Sem'!A17 -> Nitish Kumar
... A66: ='Mid Sem'!B66 -> 0 | B66: ='Mid Sem'!A66 -> 0

Sheet Quiz 2
A1: Quiz 2
A2: =Marksheet!A2 -> Physics for Computer Engineers (PHYS 1036)
D3: CO5 | E3: CO4 | F3: CO5 | G3: CO4 | H3: CO5 | I3: CO3 | J3: CO4 | K3: CO5 | L3: CO4 | S3: CO3 | T3: CO4 | U3: CO5
A4: Student Id | B4: Name | D4: Q1 | E4: Q2 | F4: Q3 | G4: Q4 | H4: Q5 | I4: Q6 | J4: Q7 | K4: Q8 | L4: Q9 | M4: Q10 | N4: Q11 | O4: Total | P4: Sign | V4: Total
B5: Max Marks | C5: P/A | D5: 1 | E5: 1 | F5: 1 | G5: 1 | H5: 1 | I5: 3 | J5: 3 | K5: 2 | L5: 2 | O5: =SUM(D5:L5) -> 15 | S5: =SUM(I5) -> 3 | T5: =SUM(E5,G5,J5,L5) -> 7 | U5: =SUM(D5,F5,H5,K5) -> 5 | V5: =SUM(S5:U5) -> 15
A6: ='Mid Sem'!B6 -> 590029213 | B6: ='Mid Sem'!A6 -> Aadya Dubey | C6: TRUE | D6: 1 | E6: 1 | F6: 1 | G6: 1 | H6: 1 | I6: 3 | J6: 3 | K6: 2 | L6: 2 | O6: =SUM(D6:L6) -> 15 | S6: =SUM(I6) -> 3 | T6: =SUM(E6,G6,J6,L6) -> 7 | U6: =SUM(D6,F6,H6,K6) -> 5 | V6: =SUM(S6:U6) -> 15
A7: ='Mid Sem'!B7 -> 590029270 | B7: ='Mid Sem'!A7 -> Aditya Vishwakarma | C7: TRUE | D7: 1 | E7: 1 | F7: 1 | G7: 1 | H7: 1 | I7: 3 | J7: 3 | K7: 2 | L7: 2 | O7: =SUM(D7:L7) -> 15 | S7: =SUM(I7) -> 3 | T7: =SUM(E7,G7,J7,L7) -> 7 | U7: =SUM(D7,F7,H7,K7) -> 5 | V7: =SUM(S7:U7) -> 15
A8: ='Mid Sem'!B8 -> 590029204 | B8: ='Mid Sem'!A8 -> Arjun | C8: TRUE | D8: 1 | E8: 1 | F8: 1 | G8: 1 | H8: 1 | I8: 1 | J8: 1 | K8: 1.5 | L8: 2 | O8: =SUM(D8:L8) -> 10.5 | S8: =SUM(I8) -> 1 | T8: =SUM(E8,G8,J8,L8) -> 5 | U8: =SUM(D8,F8,H8,K8) -> 4.5 | V8: =SUM(S8:U8) -> 10.5
A9: ='Mid Sem'!B9 -> 590029109 | B9: ='Mid Sem'!A9 -> Aryan Yadav | C9: TRUE | D9: 1 | E9: 1 | F9: 1 | G9: 1 | H9: 1 | I9: 3 | J9: 3 | K9: 2 | L9: 2 | O9: =SUM(D9:L9) -> 15 | S9: =SUM(I9) -> 3 | T9: =SUM(E9,G9,J9,L9) -> 7 | U9: =SUM(D9,F9,H9,K9) -> 5 | V9: =SUM(S9:U9) -> 15
A10: ='Mid Sem'!B10 -> 590029070 | B10: ='Mid Sem'!A10 -> Astik Patel | C10: TRUE | D10: 1 | E10: 1 | F10: 1 | G10: 1 | H10: 1 | I10: 3 | J10: 3 | K10: 2 | L10: 2 | O10: =SUM(D10:L10) -> 15 | S10: =SUM(I10) -> 3 | T10: =SUM(E10,G10,J10,L10) -> 7 | U10: =SUM(D10,F10,H10,K10) -> 5 | V10: =SUM(S10:U10) -> 15
A11: ='Mid Sem'!B11 -> 590029157 | B11: ='Mid Sem'!A11 -> Ayush Mohan | C11: TRUE | D11: 1 | E11: 1 | F11: 1 | G11: 1 | H11: 1 | I11: 2.5 | J11: 1 | K11: 2 | L11: 2 | O11: =SUM(D11:L11) -> 12.5 | S11: =SUM(I11) -> 2.5 | T11: =SUM(E11,G11,J11,L11) -> 5 | U11: =SUM(D11,F11,H11,K11) -> 5 | V11: =SUM(S11:U11) -> 12.5
A12: ='Mid Sem'!B12 -> 590027157 | B12: ='Mid Sem'!A12 -> Bhanu Purohit | C12: TRUE | D12: 1 | E12: 1 | F12: 1 | G12: 1 | H12: 1 | I12: 0 | J12: 3 | K12: 1 | L12: 1 | O12: =SUM(D12:L12) -> 10 | S12: =SUM(I12) -> 0 | T12: =SUM(E12,G12,J12,L12) -> 6 | U12: =SUM(D12,F12,H12,K12) -> 4 | V12: =SUM(S12:U12) -> 10
A13: ='Mid Sem'!B13 -> 590029274 | B13: ='Mid Sem'!A13 -> Biswabandya Mohanty | C13: TRUE | D13: 1 | E13: 1 | F13: 1 | G13: 1 | H13: 1 | I13: 3 | J13: 2 | K13: 2 | L13: 2 | O13: =SUM(D13:L13) -> 14 | S13: =SUM(I13) -> 3 | T13: =SUM(E13,G13,J13,L13) -> 6 | U13: =SUM(D13,F13,H13,K13) -> 5 | V13: =SUM(S13:U13) -> 14
A14: ='Mid Sem'!B14 -> 590028572 | B14: ='Mid Sem'!A14 -> Eashan Vashisht | C14: TRUE | D14: 1 | E14: 1 | F14: 1 | G14: 1 | H14: 1 | I14: 3 | J14: 0 | K14: 2 | L14: 2 | O14: =SUM(D14:L14) -> 12 | S14: =SUM(I14) -> 3 | T14: =SUM(E14,G14,J14,L14) -> 4 | U14: =SUM(D14,F14,H14,K14) -> 5 | V14: =SUM(S14:U14) -> 12
A15: ='Mid Sem'!B15 -> 590029230 | B15: ='Mid Sem'!A15 -> Hardik Joshi | C15: FALSE | O15: =SUM(D15:L15) -> 0 | S15: =SUM(I15) -> 0 | T15: =SUM(E15,G15,J15,L15) -> 0 | U15: =SUM(D15,F15,H15,K15) -> 0 | V15: =SUM(S15:U15) -> 0
A16: ='Mid Sem'!B16 -> 590029169 | B16: ='Mid Sem'!A16 -> Hrithvik Bhardwaj | C16: TRUE | D16: 1 | E16: 1 | F16: 1 | G16: 1 | H16: 1 | I16: 3 | J16: 3 | K16: 0 | L16: 2 | O16: =SUM(D16:L16) -> 13 | S16: =SUM(I16) -> 3 | T16: =SUM(E16,G16,J16,L16) -> 7 | U16: =SUM(D16,F16,H16,K16) -> 3 | V16: =SUM(S16:U16) -> 13
A17: ='Mid Sem'!B17 -> 590029112 | B17: ='Mid Sem'!A17 -> Nitish Kumar | C17: TRUE | D17: 1 | E17: 0 | F17: 0 | G17: 1 | H17: 1 | I17: 1 | J17: 2 | K17: 0 | L17: 0 | O17: =SUM(D17:L17) -> 6 | S17: =SUM(I17) -> 1 | T17: =SUM(E17,G17,J17,L17) -> 3 | U17: =SUM(D17,F17,H17,K17) -> 2 | V17: =SUM(S17:U17) -> 6
A18: ='Mid Sem'!B18 -> 590025556 | B18: ='Mid Sem'!A18 -> Omkareshwar Chaubey | C18: TRUE | D18: 1 | E18: 1 | F18: 1 | G18: 1 | H18: 1 | I18: 3 | J18: 3 | K18: 2 | L18: 2 | O18: =SUM(D18:L18) -> 15 | S18: =SUM(I18) -> 3 | T18: =SUM(E18,G18,J18,L18) -> 7 | U18: =SUM(D18,F18,H18,K18) -> 5 | V18: =SUM(S18:U18) -> 15
A19: ='Mid Sem'!B19 -> 590027830 | B19: ='Mid Sem'!A19 -> Pavani Jain | C19: TRUE | D19: 1 | E19: 0 | F19: 1 | G19: 0 | H19: 1 | I19: 1 | J19: 2 | K19: 2 | L19: 2 | O19: =SUM(D19:L19) -> 10 | S19: =SUM(I19) -> 1 | T19: =SUM(E19,G19,J19,L19) -> 4 | U19: =SUM(D19,F19,H19,K19) -> 5 | V19: =SUM(S19:U19) -> 10
A20: ='Mid Sem'!B20 -> 590028360 | B20: ='Mid Sem'!A20 -> Prapti Uniyal | C20: TRUE | D20: 1 | E20: 1 | F20: 1 | G20: 1 | H20: 1 | I20: 3 | J20: 3 | K20: 1 | L20: 2 | O20: =SUM(D20:L20) -> 14 | S20: =SUM(I20) -> 3 | T20: =SUM(E20,G20,J20,L20) -> 7 | U20: =SUM(D20,F20,H20,K20) -> 4 | V20: =SUM(S20:U20) -> 14
A21: ='Mid Sem'!B21 -> 590029237 | B21: ='Mid Sem'!A21 -> Priyadarshi Prabhakar | C21: TRUE | D21: 1 | E21: 1 | F21: 1 | G21: 1 | H21: 1 | I21: 1 | J21: 0 | K21: 2 | L21: 2 | O21: =SUM(D21:L21) -> 10 | S21: =SUM(I21) -> 1 | T21: =SUM(E21,G21,J21,L21) -> 4 | U21: =SUM(D21,F21,H21,K21) -> 5 | V21: =SUM(S21:U21) -> 10
A22: ='Mid Sem'!B22 -> 590029079 | B22: ='Mid Sem'!A22 -> Radhe Patel | C22: FALSE | O22: =SUM(D22:L22) -> 0 | S22: =SUM(I22) -> 0 | T22: =SUM(E22,G22,J22,L22) -> 0 | U22: =SUM(D22,F22,H22,K22) -> 0 | V22: =SUM(S22:U22) -> 0
A23: ='Mid Sem'!B23 -> 590029145 | B23: ='Mid Sem'!A23 -> Rishika Purushotham | C23: TRUE | D23: 1 | E23: 1 | F23: 1 | G23: 1 | H23: 1 | I23: 3 | J23: 3 | K23: 2 | L23: 2 | O23: =SUM(D23:L23) -> 15 | S23: =SUM(I23) -> 3 | T23: =SUM(E23,G23,J23,L23) -> 7 | U23: =SUM(D23,F23,H23,K23) -> 5 | V23: =SUM(S23:U23) -> 15
A24: ='Mid Sem'!B24 -> 590029209 | B24: ='Mid Sem'!A24 -> Rishiv Kumar | C24: TRUE | D24: 1 | E24: 1 | F24: 1 | G24: 1 | H24: 1 | I24: 1 | J24: 0 | K24: 0 | L24: 2 | O24: =SUM(D24:L24) -> 8 | S24: =SUM(I24) -> 1 | T24: =SUM(E24,G24,J24,L24) -> 4 | U24: =SUM(D24,F24,H24,K24) -> 3 | V24: =SUM(S24:U24) -> 8
A25: ='Mid Sem'!B25 -> 590027268 | B25: ='Mid Sem'!A25 -> Sankalp Sunil Ronge | C25: TRUE | D25: 1 | E25: 1 | F25: 0 | G25: 1 | H25: 1 | I25: 2 | J25: 0 | K25: 1 | L25: 0 | O25: =SUM(D25:L25) -> 7 | S25: =SUM(I25) -> 2 | T25: =SUM(E25,G25,J25,L25) -> 2 | U25: =SUM(D25,F25,H25,K25) -> 3 | V25: =SUM(S25:U25) -> 7
A26: ='Mid Sem'!B26 -> 590029227 | B26: ='Mid Sem'!A26 -> Sartaj Singh | C26: TRUE | D26: 1 | E26: 1 | F26: 1 | G26: 1 | H26: 1 | I26: 3 | J26: 3 | K26: 2 | L26: 2 | O26: =SUM(D26:L26) -> 15 | S26: =SUM(I26) -> 3 | T26: =SUM(E26,G26,J26,L26) -> 7 | U26: =SUM(D26,F26,H26,K26) -> 5 | V26: =SUM(S26:U26) -> 15
A27: ='Mid Sem'!B27 -> 590029241 | B27: ='Mid Sem'!A27 -> Satakshi Gupta | C27: TRUE | D27: 1 | E27: 0 | F27: 1 | G27: 1 | H27: 1 | I27: 2 | J27: 1.5 | K27: 1.5 | L27: 2 | O27: =SUM(D27:L27) -> 11 | S27: =SUM(I27) -> 2 | T27: =SUM(E27,G27,J27,L27) -> 4.5 | U27: =SUM(D27,F27,H27,K27) -> 4.5 | V27: =SUM(S27:U27) -> 11
A28: ='Mid Sem'!B28 -> 590023855 | B28: ='Mid Sem'!A28 -> Shaswat Shantanu | C28: TRUE | D28: 1 | E28: 1 | F28: 1 | G28: 1 | H28: 1 | I28: 1 | J28: 0 | K28: 2 | L28: 1 | O28: =SUM(D28:L28) -> 9 | S28: =SUM(I28) -> 1 | T28: =SUM(E28,G28,J28,L28) -> 3 | U28: =SUM(D28,F28,H28,K28) -> 5 | V28: =SUM(S28:U28) -> 9
A29: ='Mid Sem'!B29 -> 590029215 | B29: ='Mid Sem'!A29 -> Siddhant Rai | C29: TRUE | D29: 1 | E29: 1 | F29: 1 | G29: 1 | H29: 1 | I29: 3 | J29: 2 | K29: 2 | L29: 2 | O29: =SUM(D29:L29) -> 14 | S29: =SUM(I29) -> 3 | T29: =SUM(E29,G29,J29,L29) -> 6 | U29: =SUM(D29,F29,H29,K29) -> 5 | V29: =SUM(S29:U29) -> 14
A30: ='Mid Sem'!B30 -> 590029111 | B30: ='Mid Sem'!A30 -> Sidhaant Singh Jyrwa | C30: TRUE | D30: 1 | E30: 1 | F30: 1 | G30: 1 | H30: 1 | I30: 2.5 | J30: 0 | K30: 2 | L30: 2 | O30: =SUM(D30:L30) -> 11.5 | S30: =SUM(I30) -> 2.5 | T30: =SUM(E30,G30,J30,L30) -> 4 | U30: =SUM(D30,F30,H30,K30) -> 5 | V30: =SUM(S30:U30) -> 11.5
A31: ='Mid Sem'!B31 -> 590028683 | B31: ='Mid Sem'!A31 -> Subrat Singh Jadaun | C31: TRUE | D31: 1 | E31: 1 | F31: 1 | G31: 1 | H31: 1 | I31: 1 | J31: 0 | K31: 1 | L31: 2 | O31: =SUM(D31:L31) -> 9 | S31: =SUM(I31) -> 1 | T31: =SUM(E31,G31,J31,L31) -> 4 | U31: =SUM(D31,F31,H31,K31) -> 4 | V31: =SUM(S31:U31) -> 9
A32: ='Mid Sem'!B32 -> 590029121 | B32: ='Mid Sem'!A32 -> Tushita Sharma | C32: TRUE | D32: 1 | E32: 1 | F32: 1 | G32: 1 | H32: 1 | I32: 3 | J32: 3 | K32: 2 | L32: 2 | O32: =SUM(D32:L32) -> 15 | S32: =SUM(I32) -> 3 | T32: =SUM(E32,G32,J32,L32) -> 7 | U32: =SUM(D32,F32,H32,K32) -> 5 | V32: =SUM(S32:U32) -> 15
A33: ='Mid Sem'!B33 -> 590029048 | B33: ='Mid Sem'!A33 -> Vaishnavi Kumari | C33: TRUE | D33: 1 | E33: 1 | F33: 1 | G33: 1 | H33: 1 | I33: 3 | J33: 3 | K33: 1.5 | L33: 2 | O33: =SUM(D33:L33) -> 14.5 | S33: =SUM(I33) -> 3 | T33: =SUM(E33,G33,J33,L33) -> 7 | U33: =SUM(D33,F33,H33,K33) -> 4.5 | V33: =SUM(S33:U33) -> 14.5
A34: ='Mid Sem'!B34 -> 590029184 | B34: ='Mid Sem'!A34 -> Vivek Chauhan | C34: TRUE | D34: 1 | E34: 1 | F34: 1 | G34: 1 | H34: 1 | I34: 3 | J34: 3 | K34: 2 | L34: 2 | O34: =SUM(D34:L34) -> 15 | S34: =SUM(I34) -> 3 | T34: =SUM(E34,G34,J34,L34) -> 7 | U34: =SUM(D34,F34,H34,K34) -> 5 | V34: =SUM(S34:U34) -> 15
... A42: ='Mid Sem'!B42 -> 590023785 | B42: ='Mid Sem'!A42 -> Gayatri Bhatt | C42: TRUE | D42: 1 | E42: 0 | F42: 1 | G42: 1 | H42: 1 | I42: 2 | J42: 3 | K42: 2 | L42: 2 | O42: =SUM(D42:L42) -> 13 | S42: =SUM(I42) -> 2 | T42: =SUM(E42,G42,J42,L42) -> 6 | U42: =SUM(D42,F42,H42,K42) -> 5 | V42: =SUM(S42:U42) -> 13
A43: ='Mid Sem'!B43 -> 590029264 | B43: ='Mid Sem'!A43 -> Harsh Mudgal | C43: FALSE | O43: =SUM(D43:L43) -> 0 | S43: =SUM(I43) -> 0 | T43: =SUM(E43,G43,J43,L43) -> 0 | U43: =SUM(D43,F43,H43,K43) -> 0 | V43: =SUM(S43:U43) -> 0
A44: ='Mid Sem'!B44 -> 590029042 | B44: ='Mid Sem'!A44 -> Kanan Nidhania | C44: FALSE | O44: =SUM(D44:L44) -> 0 | S44: =SUM(I44) -> 0 | T44: =SUM(E44,G44,J44,L44) -> 0 | U44: =SUM(D44,F44,H44,K44) -> 0 | V44: =SUM(S44:U44) -> 0
A45: ='Mid Sem'!B45 -> 590029336 | B45: ='Mid Sem'!A45 -> Kanishka Diwakar | C45: TRUE | D45: 1 | E45: 1 | F45: 1 | G45: 1 | H45: 1 | I45: 2 | J45: 0 | K45: 2 | L45: 2 | O45: =SUM(D45:L45) -> 11 | S45: =SUM(I45) -> 2 | T45: =SUM(E45,G45,J45,L45) -> 4 | U45: =SUM(D45,F45,H45,K45) -> 5 | V45: =SUM(S45:U45) -> 11
A46: ='Mid Sem'!B46 -> 590029233 | B46: ='Mid Sem'!A46 -> Keshav Chahda | C46: FALSE | O46: =SUM(D46:L46) -> 0 | S46: =SUM(I46) -> 0 | T46: =SUM(E46,G46,J46,L46) -> 0 | U46: =SUM(D46,F46,H46,K46) -> 0 | V46: =SUM(S46:U46) -> 0
A47: ='Mid Sem'!B47 -> 590029328 | B47: ='Mid Sem'!A47 -> Lakshay Dhanda | C47: TRUE | D47: 1 | E47: 1 | F47: 1 | G47: 1 | H47: 1 | I47: 3 | J47: 3 | K47: 2 | L47: 2 | O47: =SUM(D47:L47) -> 15 | S47: =SUM(I47) -> 3 | T47: =SUM(E47,G47,J47,L47) -> 7 | U47: =SUM(D47,F47,H47,K47) -> 5 | V47: =SUM(S47:U47) -> 15
...

Sheet Assignment 1
A1: Assignment 1
A2: =Marksheet!A2 -> Physics for Computer Engineers (PHYS 1036)
C3: CO1 | D3: CO1 | E3: CO1 | F3: CO1 | G3: CO1 | H3: CO2 | I3: CO2 | J3: CO2 | K3: CO2 | L3: CO2 | R3: CO1 | S3: CO2
A4: Student Id | B4: Name | C4: Q1 | D4: Q2 | E4: Q3 | F4: Q4 | G4: Q5 | H4: Q6 | I4: Q7 | J4: Q8 | K4: Q9 | L4: Q10 | N4: Total | O4: Sign | T4: Total
B5: Max Marks | C5: 20 | D5: 20 | E5: 20 | F5: 20 | G5: 15 | H5: 20 | I5: 15 | J5: 5 | K5: 10 | L5: 5 | N5: =SUM(C5:L5) -> 150 | R5: =SUM(C5:G5) -> 95 | S5: =SUM(H5:L5) -> 55 | T5: =SUM(R5:S5) -> 150
A6: ='Mid Sem'!B6 -> 590029213 | B6: ='Mid Sem'!A6 -> Aadya Dubey | C6: 20 | D6: 20 | E6: 18 | F6: 18 | G6: 15 | H6: 19 | I6: 15 | J6: 5 | K6: 10 | L6: 5 | N6: =SUM(C6:L6) -> 145 | R6: =SUM(C6:G6) -> 91 | S6: =SUM(H6:L6) -> 54 | T6: =SUM(R6:S6) -> 145 | U6: =R6/10 -> 9.1 | V6: =S6/10 -> 5.4
A7: ='Mid Sem'!B7 -> 590029270 | B7: ='Mid Sem'!A7 -> Aditya Vishwakarma | C7: 18 | D7: 20 | E7: 20 | F7: 13 | G7: 15 | H7: 19 | I7: 15 | J7: 5 | K7: 10 | L7: 5 | N7: =SUM(C7:L7) -> 140 | R7: =SUM(C7:G7) -> 86 | S7: =SUM(H7:L7) -> 54 | T7: =SUM(R7:S7) -> 140 | U7: =R7/10 -> 8.6 | V7: =S7/10 -> 5.4
A8: ='Mid Sem'!B8 -> 590029204 | B8: ='Mid Sem'!A8 -> Arjun | C8: 18 | D8: 18 | E8: 20 | F8: 18 | G8: 14 | H8: 19 | I8: 15 | J8: 5 | K8: 10 | L8: 5 | N8: =SUM(C8:L8) -> 142 | R8: =SUM(C8:G8) -> 88 | S8: =SUM(H8:L8) -> 54 | T8: =SUM(R8:S8) -> 142 | U8: =R8/10 -> 8.8 | V8: =S8/10 -> 5.4
A9: ='Mid Sem'!B9 -> 590029109 | B9: ='Mid Sem'!A9 -> Aryan Yadav | C9: 20 | D9: 20 | E9: 20 | F9: 20 | G9: 15 | H9: 20 | I9: 15 | J9: 5 | K9: 10 | L9: 5 | N9: =SUM(C9:L9) -> 150 | R9: =SUM(C9:G9) -> 95 | S9: =SUM(H9:L9) -> 55 | T9: =SUM(R9:S9) -> 150 | U9: =R9/10 -> 9.5 | V9: =S9/10 -> 5.5
A10: ='Mid Sem'!B10 -> 590029070 | B10: ='Mid Sem'!A10 -> Astik Patel | C10: 20 | D10: 20 | E10: 18 | F10: 15 | G10: 15 | H10: 19 | I10: 15 | J10: 5 | K10: 10 | L10: 5 | N10: =SUM(C10:L10) -> 142 | R10: =SUM(C10:G10) -> 88 | S10: =SUM(H10:L10) -> 54 | T10: =SUM(R10:S10) -> 142 | U10: =R10/10 -> 8.8 | V10: =S10/10 -> 5.4
A11: ='Mid Sem'!B11 -> 590029157 | B11: ='Mid Sem'!A11 -> Ayush Mohan | C11: 18 | D11: 18 | E11: 20 | F11: 16 | G11: 13 | H11: 19 | I11: 14 | J11: 5 | K11: 8 | L11: 5 | N11: =SUM(C11:L11) -> 136 | R11: =SUM(C11:G11) -> 85 | S11: =SUM(H11:L11) -> 51 | T11: =SUM(R11:S11) -> 136 | U11: =R11/10 -> 8.5 | V11: =S11/10 -> 5.1
A12: ='Mid Sem'!B12 -> 590027157 | B12: ='Mid Sem'!A12 -> Bhanu Purohit | C12: 18 | D12: 19 | E12: 20 | F12: 18 | G12: 13 | H12: 18 | I12: 15 | J12: 5 | K12: 8 | L12: 5 | N12: =SUM(C12:L12) -> 139 | R12: =SUM(C12:G12) -> 88 | S12: =SUM(H12:L12) -> 51 | T12: =SUM(R12:S12) -> 139 | U12: =R12/10 -> 8.8 | V12: =S12/10 -> 5.1
A13: ='Mid Sem'!B13 -> 590029274 | B13: ='Mid Sem'!A13 -> Biswabandya Mohanty | C13: 18 | D13: 18 | E13: 20 | F13: 18 | G13: 13 | H13: 18 | I13: 15 | J13: 5 | K13: 8 | L13: 5 | N13: =SUM(C13:L13) -> 138 | R13: =SUM(C13:G13) -> 87 | S13: =SUM(H13:L13) -> 51 | T13: =SUM(R13:S13) -> 138 | U13: =R13/10 -> 8.7 | V13: =S13/10 -> 5.1
A14: ='Mid Sem'!B14 -> 590028572 | B14: ='Mid Sem'!A14 -> Eashan Vashisht | C14: 18 | D14: 20 | E14: 20 | F14: 18 | G14: 15 | H14: 20 | I14: 15 | J14: 5 | K14: 9 | L14: 5 | N14: =SUM(C14:L14) -> 145 | R14: =SUM(C14:G14) -> 91 | S14: =SUM(H14:L14) -> 54 | T14: =SUM(R14:S14) -> 145 | U14: =R14/10 -> 9.1 | V14: =S14/10 -> 5.4
A15: ='Mid Sem'!B15 -> 590029230 | B15: ='Mid Sem'!A15 -> Hardik Joshi | N15: =SUM(C15:L15) -> 0 | R15: =SUM(C15:G15) -> 0 | S15: =SUM(H15:L15) -> 0 | T15: =SUM(R15:S15) -> 0 | U15: =R15/10 -> 0 | V15: =S15/10 -> 0
A16: ='Mid Sem'!B16 -> 590029169 | B16: ='Mid Sem'!A16 -> Hrithvik Bhardwaj | C16: 18 | D16: 20 | E16: 20 | F16: 12 | G16: 14 | H16: 19 | I16: 15 | J16: 5 | K16: 9 | L16: 5 | N16: =SUM(C16:L16) -> 137 | R16: =SUM(C16:G16) -> 84 | S16: =SUM(H16:L16) -> 53 | T16: =SUM(R16:S16) -> 137 | U16: =R16/10 -> 8.4 | V16: =S16/10 -> 5.3
A17: ='Mid Sem'!B17 -> 590029112 | B17: ='Mid Sem'!A17 -> Nitish Kumar | C17: 19 | D17: 18 | E17: 20 | F17: 18 | G17: 13 | H17: 16 | I17: 14 | J17: 5 | K17: 7 | L17: 4 | N17: =SUM(C17:L17) -> 134 | R17: =SUM(C17:G17) -> 88 | S17: =SUM(H17:L17) -> 46 | T17: =SUM(R17:S17) -> 134 | U17: =R17/10 -> 8.8 | V17: =S17/10 -> 4.6
A18: ='Mid Sem'!B18 -> 590025556 | B18: ='Mid Sem'!A18 -> Omkareshwar Chaubey | C18: 19 | D18: 18 | E18: 20 | F18: 18 | G18: 13 | H18: 19 | I18: 15 | J18: 5 | K18: 8 | L18: 5 | N18: =SUM(C18:L18) -> 140 | R18: =SUM(C18:G18) -> 88 | S18: =SUM(H18:L18) -> 52 | T18: =SUM(R18:S18) -> 140 | U18: =R18/10 -> 8.8 | V18: =S18/10 -> 5.2
A19: ='Mid Sem'!B19 -> 590027830 | B19: ='Mid Sem'!A19 -> Pavani Jain | C19: 20 | D19: 20 | E19: 20 | F19: 18 | G19: 15 | H19: 19 | I19: 15 | J19: 5 | K19: 10 | L19: 5 | N19: =SUM(C19:L19) -> 147 | R19: =SUM(C19:G19) -> 93 | S19: =SUM(H19:L19) -> 54 | T19: =SUM(R19:S19) -> 147 | U19: =R19/10 -> 9.3 | V19: =S19/10 -> 5.4
A20: ='Mid Sem'!B20 -> 590028360 | B20: ='Mid Sem'!A20 -> Prapti Uniyal | C20: 18 | D20: 18 | E20: 20 | F20: 17 | G20: 13 | H20: 17 | I20: 14 | J20: 5 | K20: 8 | L20: 5 | N20: =SUM(C20:L20) -> 135 | R20: =SUM(C20:G20) -> 86 | S20: =SUM(H20:L20) -> 49 | T20: =SUM(R20:S20) -> 135 | U20: =R20/10 -> 8.6 | V20: =S20/10 -> 4.9
A21: ='Mid Sem'!B21 -> 590029237 | B21: ='Mid Sem'!A21 -> Priyadarshi Prabhakar | C21: 20 | D21: 20 | E21: 20 | F21: 18 | G21: 13 | H21: 19 | I21: 15 | J21: 5 | K21: 8 | L21: 5 | N21: =SUM(C21:L21) -> 143 | R21: =SUM(C21:G21) -> 91 | S21: =SUM(H21:L21) -> 52 | T21: =SUM(R21:S21) -> 143 | U21: =R21/10 -> 9.1 | V21: =S21/10 -> 5.2
A22: ='Mid Sem'!B22 -> 590029079 | B22: ='Mid Sem'!A22 -> Radhe Patel | N22: =SUM(C22:L22) -> 0 | R22: =SUM(C22:G22) -> 0 | S22: =SUM(H22:L22) -> 0 | T22: =SUM(R22:S22) -> 0 | U22: =R22/10 -> 0 | V22: =S22/10 -> 0
A23: ='Mid Sem'!B23 -> 590029145 | B23: ='Mid Sem'!A23 -> Rishika Purushotham | C23: 19 | D23: 20 | E23: 19 | F23: 13 | G23: 15 | H23: 19 | I23: 13 | J23: 5 | K23: 10 | L23: 3 | N23: =SUM(C23:L23) -> 136 | R23: =SUM(C23:G23) -> 86 | S23: =SUM(H23:L23) -> 50 | T23: =SUM(R23:S23) -> 136 | U23: =R23/10 -> 8.6 | V23: =S23/10 -> 5
A24: ='Mid Sem'!B24 -> 590029209 | B24: ='Mid Sem'!A24 -> Rishiv Kumar | N24: =SUM(C24:L24) -> 0 | R24: =SUM(C24:G24) -> 0 | S24: =SUM(H24:L24) -> 0 | T24: =SUM(R24:S24) -> 0 | U24: =R24/10 -> 0 | V24: =S24/10 -> 0
A25: ='Mid Sem'!B25 -> 590027268 | B25: ='Mid Sem'!A25 -> Sankalp Sunil Ronge | N25: =SUM(C25:L25) -> 0 | R25: =SUM(C25:G25) -> 0 | S25: =SUM(H25:L25) -> 0 | T25: =SUM(R25:S25) -> 0 | U25: =R25/10 -> 0 | V25: =S25/10 -> 0
A26: ='Mid Sem'!B26 -> 590029227 | B26: ='Mid Sem'!A26 -> Sartaj Singh | C26: 20 | D26: 20 | E26: 20 | F26: 18 | G26: 15 | H26: 20 | I26: 15 | J26: 5 | K26: 10 | L26: 5 | N26: =SUM(C26:L26) -> 148 | R26: =SUM(C26:G26) -> 93 | S26: =SUM(H26:L26) -> 55 | T26: =SUM(R26:S26) -> 148 | U26: =R26/10 -> 9.3 | V26: =S26/10 -> 5.5
A27: ='Mid Sem'!B27 -> 590029241 | B27: ='Mid Sem'!A27 -> Satakshi Gupta | C27: 18 | D27: 18 | E27: 20 | F27: 18 | G27: 13 | H27: 18 | I27: 15 | J27: 5 | K27: 8 | L27: 5 | N27: =SUM(C27:L27) -> 138 | R27: =SUM(C27:G27) -> 87 | S27: =SUM(H27:L27) -> 51 | T27: =SUM(R27:S27) -> 138 | U27: =R27/10 -> 8.7 | V27: =S27/10 -> 5.1
A28: ='Mid Sem'!B28 -> 590023855 | B28: ='Mid Sem'!A28 -> Shaswat Shantanu | N28: =SUM(C28:L28) -> 0 | R28: =SUM(C28:G28) -> 0 | S28: =SUM(H28:L28) -> 0 | T28: =SUM(R28:S28) -> 0 | U28: =R28/10 -> 0 | V28: =S28/10 -> 0
A29: ='Mid Sem'!B29 -> 590029215 | B29: ='Mid Sem'!A29 -> Siddhant Rai | C29: 18 | D29: 18 | E29: 20 | F29: 18 | G29: 15 | H29: 18 | I29: 13 | J29: 5 | K29: 10 | L29: 5 | N29: =SUM(C29:L29) -> 140 | R29: =SUM(C29:G29) -> 89 | S29: =SUM(H29:L29) -> 51 | T29: =SUM(R29:S29) -> 140 | U29: =R29/10 -> 8.9 | V29: =S29/10 -> 5.1
A30: ='Mid Sem'!B30 -> 590029111 | B30: ='Mid Sem'!A30 -> Sidhaant Singh Jyrwa | C30: 0 | D30: 0 | E30: 20 | F30: 16 | G30: 0 | H30: 0 | I30: 10 | J30: 0 | K30: 0 | L30: 5 | N30: =SUM(C30:L30) -> 51 | R30: =SUM(C30:G30) -> 36 | S30: =SUM(H30:L30) -> 15 | T30: =SUM(R30:S30) -> 51 | U30: =R30/10 -> 3.6 | V30: =S30/10 -> 1.5
A31: ='Mid Sem'!B31 -> 590028683 | B31: ='Mid Sem'!A31 -> Subrat Singh Jadaun | C31: 18 | D31: 20 | E31: 20 | F31: 18 | G31: 15 | H31: 17 | I31: 12 | J31: 5 | K31: 10 | L31: 5 | N31: =SUM(C31:L31) -> 140 | R31: =SUM(C31:G31) -> 91 | S31: =SUM(H31:L31) -> 49 | T31: =SUM(R31:S31) -> 140 | U31: =R31/10 -> 9.1 | V31: =S31/10 -> 4.9
A32: ='Mid Sem'!B32 -> 590029121 | B32: ='Mid Sem'!A32 -> Tushita Sharma | C32: 20 | D32: 20 | E32: 20 | F32: 18 | G32: 13 | H32: 20 | I32: 15 | J32: 5 | K32: 8 | L32: 5 | N32: =SUM(C32:L32) -> 144 | R32: =SUM(C32:G32) -> 91 | S32: =SUM(H32:L32) -> 53 | T32: =SUM(R32:S32) -> 144 | U32: =R32/10 -> 9.1 | V32: =S32/10 -> 5.3
A33: ='Mid Sem'!B33 -> 590029048 | B33: ='Mid Sem'!A33 -> Vaishnavi Kumari | C33: 18 | D33: 20 | E33: 20 | F33: 18 | G33: 15 | H33: 20 | I33: 15 | J33: 5 | K33: 10 | L33: 5 | N33: =SUM(C33:L33) -> 146 | R33: =SUM(C33:G33) -> 91 | S33: =SUM(H33:L33) -> 55 | T33: =SUM(R33:S33) -> 146 | U33: =R33/10 -> 9.1 | V33: =S33/10 -> 5.5
