Workbook

Sheet Marksheet
A1: Final Marks
A2: Computational Techniques (CSEG 1023)
A3: Cohort Name | B3: Name | C3: SAP ID | D3: Column1 | E3: CT 1 | F3: CT 2 | G3: Quiz 1 | H3: File | I3: Presentation | J3: Column7 | K3: Column8 | L3: Total | M3: Sign | N3: Grade
C4: Max Marks | E4: 40 | F4: 40 | G4: 10 | H4: 25 | I4: 25 | L4: =SUM(Table1[[#This Row],[CT 1]]/2, Table1[[#This Row],[CT 2]]/2, Table1[[#This Row],[Quiz 1]], Table1[[#This Row],[File]], Table1[[#This Row],[Presentation]]) -> 100 | N4: {=_xlfn.IFS( Table1[[#This Row],[Total]]>=85, "O", Table1[[#This Row],[Total]]>=75, "A", Table1[[#This Row],[Total]]>=65, "B", Table1[[#This Row],[Total]]>=55, "C", Table1[[#This Row],[Total]]>=45, "D", Table1[[#This Row],[Total]]>=35, "E", TRUE, "F" )} -> O
B5: Aanya Nautiyal | C5: 590027532 | E5: {=_xlfn.XLOOKUP( TRIM(Table1[[#This Row],[Name ]]), TRIM('Class Test 1'!B:B), 'Class Test 1'!N:N, "" )} -> 9 | F5: {=_xlfn.XLOOKUP( TRIM(Table1[[#This Row],[Name ]]), TRIM('Class Test 2'!B6:B52), 'Class Test 2'!N6:N52, "")} -> 0 | G5: =_xlfn.XLOOKUP( LEFT(Table1[[#This Row],[Name ]], FIND(" ", Table1[[#This Row],[Name ]] & " ") - 1), Table2[First name], Table2[Grade/10.00], "" ) -> 9 | H5: ='Final Presentation'!C6 -> 22 | I5: ='Final Presentation'!D6 -> 19 | L5: =SUM(Table1[[#This Row],[CT 1]]/2, Table1[[#This Row],[CT 2]]/2, Table1[[#This Row],[Quiz 1]], Table1[[#This Row],[File]], Table1[[#This Row],[Presentation]]) -> 54.5 | N5: {=_xlfn.IFS( Table1[[#This Row],[Total]]>=85, "O", Table1[[#This Row],[Total]]>=75, "A", Table1[[#This Row],[Total]]>=65, "B", Table1[[#This Row],[Total]]>=55, "C", Table1[[#This Row],[Total]]>=45, "D", Table1[[#This Row],[Total]]>=35, "E", TRUE, "F" )} -> D
B6: Aaryan Choubey | C6: 590021539 | E6: {=_xlfn.XLOOKUP( TRIM(Table1[[#This Row],[Name ]]), TRIM('Class Test 1'!B:B), 'Class Test 1'!N:N, "" )} -> 0 | F6: {=_xlfn.XLOOKUP( TRIM(Table1[[#This Row],[Name ]]), TRIM('Class Test 2'!B7:B53), 'Class Test 2'!N7:N53, "")} -> 21 | G6: =_xlfn.XLOOKUP( LEFT(Table1[[#This Row],[Name ]], FIND(" ", Table1[[#This Row],[Name ]] & " ") - 1), Table2[First name], Table2[Grade/10.00], "" ) -> 10 | H6: ='Final Presentation'!C7 -> 23 | I6: ='Final Presentation'!D7 -> 24 | L6: =SUM(Table1[[#This Row],[CT 1]]/2, Table1[[#This Row],[CT 2]]/2, Table1[[#This Row],[Quiz 1]], Table1[[#This Row],[File]], Table1[[#This Row],[Presentation]]) -> 67.5 | N6: {=_xlfn.IFS( Table1[[#This Row],[Total]]>=85, "O", Table1[[#This Row],[Total]]>=75, "A", Table1[[#This Row],[Total]]>=65, "B", Table1[[#This Row],[Total]]>=55, "C", Table1[[#This Row],[Total]]>=45, "D", Table1[[#This Row],[Total]]>=35, "E", TRUE, "F" )} -> B
B7: Aarye Singhal | C7: 590021092 | E7: {=_xlfn.XLOOKUP( TRIM(Table1[[#This Row],[Name ]]), TRIM('Class Test 1'!B:B), 'Class Test 1'!N:N, "" )} -> 30 | F7: {=_xlfn.XLOOKUP( TRIM(Table1[[#This Row],[Name ]]), TRIM('Class Test 2'!B8:B54), 'Class Test 2'!N8:N54, "")} -> 29 | G7: =_xlfn.XLOOKUP( LEFT(Table1[[#This Row],[Name ]], FIND(" ", Table1[[#This Row],[Name ]] & " ") - 1), Table2[First name], Table2[Grade/10.00], "" ) -> 10 | H7: ='Final Presentation'!C8 -> 21 | I7: ='Final Presentation'!D8 -> 23 | L7: =SUM(Table1[[#This Row],[CT 1]]/2, Table1[[#This Row],[CT 2]]/2, Table1[[#This Row],[Quiz 1]], Table1[[#This Row],[File]], Table1[[#This Row],[Presentation]]) -> 83.5 | N7: {=_xlfn.IFS( Table1[[#This Row],[Total]]>=85, "O", Table1[[#This Row],[Total]]>=75, "A", Table1[[#This Row],[Total]]>=65, "B", Table1[[#This Row],[Total]]>=55, "C", Table1[[#This Row],[Total]]>=45, "D", Table1[[#This Row],[Total]]>=35, "E", TRUE, "F" )} -> A
B8: Abhijay | C8: 590028566 | E8: {=_xlfn.XLOOKUP( TRIM(Table1[[#This Row],[Name ]]), TRIM('Class Test 1'!B:B), 'Class Test 1'!N:N, "" )} -> 16 | F8: {=_xlfn.XLOOKUP( TRIM(Table1[[#This Row],[Name ]]), TRIM('Class Test 2'!B9:B55), 'Class Test 2'!N9:N55, "")} -> 19 | G8: =_xlfn.XLOOKUP( LEFT(Table1[[#This Row],[Name ]], FIND(" ", Table1[[#This Row],[Name ]] & " ") - 1), Table2[First name], Table2[Grade/10.00], "" ) -> 10 | H8: ='Final Presentation'!C9 -> 21 | I8: ='Final Presentation'!D9 -> 24 | L8: =SUM(Table1[[#This Row],[CT 1]]/2, Table1[[#This Row],[CT 2]]/2, Table1[[#This Row],[Quiz 1]], Table1[[#This Row],[File]], Table1[[#This Row],[Presentation]]) -> 72.5 | N8: {=_xlfn.IFS( Table1[[#This Row],[Total]]>=85, "O", Table1[[#This Row],[Total]]>=75, "A", Table1[[#This Row],[Total]]>=65, "B", Table1[[#This Row],[Total]]>=55, "C", Table1[[#This Row],[Total]]>=45, "D", Table1[[#This Row],[Total]]>=35, "E", TRUE, "F" )} -> B
B9: Adarsh Xavier Dadel | C9: 590027262 | E9: {=_xlfn.XLOOKUP( TRIM(Table1[[#This Row],[Name ]]), TRIM('Class Test 1'!B:B), 'Class Test 1'!N:N, "" )} -> 14 | F9: {=_xlfn.XLOOKUP( TRIM(Table1[[#This Row],[Name ]]), TRIM('Class Test 2'!B10:B56), 'Class Test 2'!N10:N56, "")} -> 18 | G9: =_xlfn.XLOOKUP( LEFT(Table1[[#This Row],[Name ]], FIND(" ", Table1[[#This Row],[Name ]] & " ") - 1), Table2[First name], Table2[Grade/10.00], "" ) | H9: ='Final Presentation'!C10 -> 22 | I9: ='Final Presentation'!D10 -> 15 | L9: =SUM(Table1[[#This Row],[CT 1]]/2, Table1[[#This Row],[CT 2]]/2, Table1[[#This Row],[Quiz 1]], Table1[[#This Row],[File]], Table1[[#This Row],[Presentation]]) -> 53 | N9: {=_xlfn.IFS( Table1[[#This Row],[Total]]>=85, "O", Table1[[#This Row],[Total]]>=75, "A", Table1[[#This Row],[Total]]>=65, "B", Table1[[#This Row],[Total]]>=55, "C", Table1[[#This Row],[Total]]>=45, "D", Table1[[#This Row],[Total]]>=35, "E", TRUE, "F" )} -> D
B10: Aditya Guleriya | C10: 590025408 | E10: {=_xlfn.XLOOKUP( TRIM(Table1[[#This Row],[Name ]]), TRIM('Class Test 1'!B:B), 'Class Test 1'!N:N, "" )} -> 9 | F10: {=_xlfn.XLOOKUP( TRIM(Table1[[#This Row],[Name ]]), TRIM('Class Test 2'!B11:B57), 'Class Test 2'!N11:N57, "")} -> 0 | G10: =_xlfn.XLOOKUP( LEFT(Table1[[#This Row],[Name ]], FIND(" ", Table1[[#This Row],[Name ]] & " ") - 1), Table2[First name], Table2[Grade/10.00], "" ) -> 10 | H10: ='Final Presentation'!C11 -> 21 | I10: ='Final Presentation'!D11 -> 20 | L10: =SUM(Table1[[#This Row],[CT 1]]/2, Table1[[#This Row],[CT 2]]/2, Table1[[#This Row],[Quiz 1]], Table1[[#This Row],[File]], Table1[[#This Row],[Presentation]]) -> 55.5 | N10: {=_xlfn.IFS( Table1[[#This Row],[Total]]>=85, "O", Table1[[#This Row],[Total]]>=75, "A", Table1[[#This Row],[Total]]>=65, "B", Table1[[#This Row],[Total]]>=55, "C", Table1[[#This Row],[Total]]>=45, "D", Table1[[#This Row],[Total]]>=35, "E", TRUE, "F" )} -> C
B11: Akhil Kumar | C11: 590028353 | E11: {=_xlfn.XLOOKUP( TRIM(Table1[[#This Row],[Name ]]), TRIM('Class Test 1'!B:B), 'Class Test 1'!N:N, "" )} -> 19 | F11: {=_xlfn.XLOOKUP( TRIM(Table1[[#This Row],[Name ]]), TRIM('Class Test 2'!B12:B58), 'Class Test 2'!N12:N58, "")} -> 0 | G11: =_xlfn.XLOOKUP( LEFT(Table1[[#This Row],[Name ]], FIND(" ", Table1[[#This Row],[Name ]] & " ") - 1), Table2[First name], Table2[Grade/10.00], "" ) -> 8 | H11: ='Final Presentation'!C12 -> AB | I11: ='Final Presentation'!D12 -> AB | L11: =SUM(Table1[[#This Row],[CT 1]]/2, Table1[[#This Row],[CT 2]]/2, Table1[[#This Row],[Quiz 1]], Table1[[#This Row],[File]], Table1[[#This Row],[Presentation]]) -> 17.5 | N11: {=_xlfn.IFS( Table1[[#This Row],[Total]]>=85, "O", Table1[[#This Row],[Total]]>=75, "A", Table1[[#This Row],[Total]]>=65, "B", Table1[[#This Row],[Total]]>=55, "C", Table1[[#This Row],[Total]]>=45, "D", Table1[[#This Row],[Total]]>=35, "E", TRUE, "F" )} -> F
B12: Arpit Arpit | C12: 590027987 | E12: {=_xlfn.XLOOKUP( TRIM(Table1[[#This Row],[Name ]]), TRIM('Class Test 1'!B:B), 'Class Test 1'!N:N, "" )} -> 27 | F12: {=_xlfn.XLOOKUP( TRIM(Table1[[#This Row],[Name ]]), TRIM('Class Test 2'!B13:B59), 'Class Test 2'!N13:N59, "")} -> 12 | G12: =_xlfn.XLOOKUP( LEFT(Table1[[#This Row],[Name ]], FIND(" ", Table1[[#This Row],[Name ]] & " ") - 1), Table2[First name], Table2[Grade/10.00], "" ) -> 9 | H12: ='Final Presentation'!C13 -> 23 | I12: ='Final Presentation'!D13 -> AB | L12: =SUM(Table1[[#This Row],[CT 1]]/2, Table1[[#This Row],[CT 2]]/2, Table1[[#This Row],[Quiz 1]], Table1[[#This Row],[File]], Table1[[#This Row],[Presentation]]) -> 51.5 | N12: {=_xlfn.IFS( Table1[[#This Row],[Total]]>=85, "O", Table1[[#This Row],[Total]]>=75, "A", Table1[[#This Row],[Total]]>=65, "B", Table1[[#This Row],[Total]]>=55, "C", Table1[[#This Row],[Total]]>=45, "D", Table1[[#This Row],[Total]]>=35, "E", TRUE, "F" )} -> D
B13: Ayan Roy | C13: 590023231 | E13: {=_xlfn.XLOOKUP( TRIM(Table1[[#This Row],[Name ]]), TRIM('Class Test 1'!B:B), 'Class Test 1'!N:N, "" )} -> 0 | F13: {=_xlfn.XLOOKUP( TRIM(Table1[[#This Row],[Name ]]), TRIM('Class Test 2'!B14:B60), 'Class Test 2'!N14:N60, "")} -> 0 | G13: =_xlfn.XLOOKUP( LEFT(Table1[[#This Row],[Name ]], FIND(" ", Table1[[#This Row],[Name ]] & " ") - 1), Table2[First name], Table2[Grade/10.00], "" ) -> 9 | H13: ='Final Presentation'!C14 -> 23 | I13: ='Final Presentation'!D14 -> 22 | L13: =SUM(Table1[[#This Row],[CT 1]]/2, Table1[[#This Row],[CT 2]]/2, Table1[[#This Row],[Quiz 1]], Table1[[#This Row],[File]], Table1[[#This Row],[Presentation]]) -> 54 | N13: {=_xlfn.IFS( Table1[[#This Row],[Total]]>=85, "O", Table1[[#This Row],[Total]]>=75, "A", Table1[[#This Row],[Total]]>=65, "B", Table1[[#This Row],[Total]]>=55, "C", Table1[[#This Row],[Total]]>=45, "D", Table1[[#This Row],[Total]]>=35, "E", TRUE, "F" )} -> D
B14: Bhavuk Kakkar | C14: 590028954 | E14: {=_xlfn.XLOOKUP( TRIM(Table1[[#This Row],[Name ]]), TRIM('Class Test 1'!B:B), 'Class Test 1'!N:N, "" )} -> 3 | F14: {=_xlfn.XLOOKUP( TRIM(Table1[[#This Row],[Name ]]), TRIM('Class Test 2'!B15:B61), 'Class Test 2'!N15:N61, "")} -> 0 | G14: =_xlfn.XLOOKUP( LEFT(Table1[[#This Row],[Name ]], FIND(" ", Table1[[#This Row],[Name ]] & " ") - 1), Table2[First name], Table2[Grade/10.00], "" ) -> 9 | H14: ='Final Presentation'!C15 -> 23 | I14: ='Final Presentation'!D15 -> 21 | L14: =SUM(Table1[[#This Row],[CT 1]]/2, Table1[[#This Row],[CT 2]]/2, Table1[[#This Row],[Quiz 1]], Table1[[#This Row],[File]], Table1[[#This Row],[Presentation]]) -> 54.5 | N14: {=_xlfn.IFS( Table1[[#This Row],[Total]]>=85, "O", Table1[[#This Row],[Total]]>=75, "A", Table1[[#This Row],[Total]]>=65, "B", Table1[[#This Row],[Total]]>=55, "C", Table1[[#This Row],[Total]]>=45, "D", Table1[[#This Row],[Total]]>=35, "E", TRUE, "F" )} -> D
B15: Chandan Kumar | C15: 590021623 | E15: {=_xlfn.XLOOKUP( TRIM(Table1[[#This Row],[Name ]]), TRIM('Class Test 1'!B:B), 'Class Test 1'!N:N, "" )} -> 16 | F15: {=_xlfn.XLOOKUP( TRIM(Table1[[#This Row],[Name ]]), TRIM('Class Test 2'!B16:B62), 'Class Test 2'!N16:N62, "")} -> 14 | G15: =_xlfn.XLOOKUP( LEFT(Table1[[#This Row],[Name ]], FIND(" ", Table1[[#This Row],[Name ]] & " ") - 1), Table2[First name], Table2[Grade/10.00], "" ) -> 10 | H15: ='Final Presentation'!C16 -> 23 | I15: ='Final Presentation'!D16 -> 18 | L15: =SUM(Table1[[#This Row],[CT 1]]/2, Table1[[#This Row],[CT 2]]/2, Table1[[#This Row],[Quiz 1]], Table1[[#This Row],[File]], Table1[[#This Row],[Presentation]]) -> 66 | N15: {=_xlfn.IFS( Table1[[#This Row],[Total]]>=85, "O", Table1[[#This Row],[Total]]>=75, "A", Table1[[#This Row],[Total]]>=65, "B", Table1[[#This Row],[Total]]>=55, "C", Table1[[#This Row],[Total]]>=45, "D", Table1[[#This Row],[Total]]>=35, "E", TRUE, "F" )} -> B
B16: Chimmay | C16: 590027316 | E16: {=_xlfn.XLOOKUP( TRIM(Table1[[#This Row],[Name ]]), TRIM('Class Test 1'!B:B), 'Class Test 1'!N:N, "" )} -> 19 | F16: {=_xlfn.XLOOKUP( TRIM(Table1[[#This Row],[Name ]]), TRIM('Class Test 2'!B17:B63), 'Class Test 2'!N17:N63, "")} -> 14 | G16: =_xlfn.XLOOKUP( LEFT(Table1[[#This Row],[Name ]], FIND(" ", Table1[[#This Row],[Name ]] & " ") - 1), Table2[First name], Table2[Grade/10.00], "" ) | H16: ='Final Presentation'!C17 -> 23 | I16: ='Final Presentation'!D17 -> 23 | L16: =SUM(Table1[[#This Row],[CT 1]]/2, Table1[[#This Row],[CT 2]]/2, Table1[[#This Row],[Quiz 1]], Table1[[#This Row],[File]], Table1[[#This Row],[Presentation]]) -> 62.5 | N16: {=_xlfn.IFS( Table1[[#This Row],[Total]]>=85, "O", Table1[[#This Row],[Total]]>=75, "A", Table1[[#This Row],[Total]]>=65, "B", Table1[[#This Row],[Total]]>=55, "C", Table1[[#This Row],[Total]]>=45, "D", Table1[[#This Row],[Total]]>=35, "E", TRUE, "F" )} -> C
... B51: Yashi Sharma | C51: 590026540 | E51: {=_xlfn.XLOOKUP( TRIM(Table1[[#This Row],[Name ]]), TRIM('Class Test 1'!B:B), 'Class Test 1'!N:N, "" )} -> 29 | F51: {=_xlfn.XLOOKUP( TRIM(Table1[[#This Row],[Name ]]), TRIM('Class Test 2'!B52:B98), 'Class Test 2'!N52:N98, "")} -> 0 | G51: =_xlfn.XLOOKUP( LEFT(Table1[[#This Row],[Name ]], FIND(" ", Table1[[#This Row],[Name ]] & " ") - 1), Table2[First name], Table2[Grade/10.00], "" ) -> 9 | H51: ='Final Presentation'!C52 -> 22 | I51: ='Final Presentation'!D52 -> 19 | L51: =SUM(Table1[[#This Row],[CT 1]]/2, Table1[[#This Row],[CT 2]]/2, Table1[[#This Row],[Quiz 1]], Table1[[#This Row],[File]], Table1[[#This Row],[Presentation]]) -> 64.5 | N51: {=_xlfn.IFS( Table1[[#This Row],[Total]]>=85, "O", Table1[[#This Row],[Total]]>=75, "A", Table1[[#This Row],[Total]]>=65, "B", Table1[[#This Row],[Total]]>=55, "C", Table1[[#This Row],[Total]]>=45, "D", Table1[[#This Row],[Total]]>=35, "E", TRUE, "F" )} -> C

Sheet Quiz_1
A1: First name | B1: Last name | C1: Name | D1: Grade/10.00
A2: Aanya | B2: Nautiyal | C2: =_xlfn.TEXTJOIN(" ", TRUE, A2, B2) -> Aanya Nautiyal | D2: 9
A3: Aaryan | B3: Choubey | C3: =_xlfn.TEXTJOIN(" ", TRUE, A3, B3) -> Aaryan Choubey | D3: 10
A4: Aarye | B4: Singhal | C4: =_xlfn.TEXTJOIN(" ", TRUE, A4, B4) -> Aarye Singhal | D4: 10
A5: Abhijay | B5: . | C5: =_xlfn.TEXTJOIN(" ", TRUE, A5, B5) -> Abhijay . | D5: 10
A6: Adarsh Xavier | B6: Dadel | C6: =_xlfn.TEXTJOIN(" ", TRUE, A6, B6) -> Adarsh Xavier Dadel | D6: 9
A7: Aditya | B7: Guleriya | C7: =_xlfn.TEXTJOIN(" ", TRUE, A7, B7) -> Aditya Guleriya | D7: 10
A8: Akhil | B8: Kumar | C8: =_xlfn.TEXTJOIN(" ", TRUE, A8, B8) -> Akhil Kumar | D8: 8
A9: Arpit | B9: Arpit | C9: =_xlfn.TEXTJOIN(" ", TRUE, A9, B9) -> Arpit Arpit | D9: 9
A10: AYAN | B10: ROY | C10: =_xlfn.TEXTJOIN(" ", TRUE, A10, B10) -> AYAN ROY | D10: 9
A11: Bhavuk | B11: Kakkar | C11: =_xlfn.TEXTJOIN(" ", TRUE, A11, B11) -> Bhavuk Kakkar | D11: 9
A12: Chandan | B12: Kumar | C12: =_xlfn.TEXTJOIN(" ", TRUE, A12, B12) -> Chandan Kumar | D12: 10
A13: Chinmay | B13: . | C13: =_xlfn.TEXTJOIN(" ", TRUE, A13, B13) -> Chinmay . | D13: 9
... A44: Yashi | B44: sharma | C44: =_xlfn.TEXTJOIN(" ", TRUE, A44, B44) -> Yashi sharma | D44: 9

Sheet Class Test 1
A1: Class Test 1
A2: Computational Techniques (CSEG 1023)
C3: CO1 | D3: CO2 | E3: CO1 | F3: CO2 | G3: CO1 | H3: CO2 | I3: CO2 | J3: CO2 | K3: CO1 | L3: CO2
A4: Student Id | B4: Name | C4: Q1 | D4: Q2 | E4: Q3 | F4: Q4 | G4: Q5 | H4: Q6 | I4: Q7 | J4: Q8 | K4: Q9 | L4: Q10 | M4: Q11 | N4: TOT | O4: Total | P4: Sign
C5: 3 | D5: 3 | E5: 3 | F5: 3 | G5: 3 | H5: 5 | I5: 5 | J5: 5 | K5: 5 | L5: 5 | N5: 40 | O5: 40
A6: 590027532 | B6: Aanya Nautiyal | C6: F | D6: T | E6: T | F6: N | G6: T | H6: F | I6: F | J6: N | K6: N | L6: F | N6: 9 | O6: 4.5
A7: 590021539 | B7: Aaryan Choubey | C7: N | D7: N | E7: N | F7: N | G7: N | H7: N | I7: N | J7: N | K7: N | L7: N | N7: 0 | O7: 0
A8: 590021092 | B8: Aarye Singhal | C8: T | D8: T | E8: T | F8: T | G8: T | H8: F | I8: F | J8: T | K8: T | L8: T | N8: 30 | O8: 27.5
A9: 590028566 | B9: Abhijay | C9: T | D9: N | E9: N | F9: F | G9: T | H9: T | I9: N | J9: N | K9: T | L9: N | N9: 16 | O9: 15.25
A10: 590027262 | B10: Adarsh Xavier Dadel | C10: T | D10: F | E10: T | F10: F | G10: T | H10: T | I10: N | J10: F | K10: F | L10: F | N10: 14 | O10: 8.75
A11: 590025408 | B11: Aditya Guleriya | C11: T | D11: T | E11: T | F11: F | G11: F | H11: F | I11: F | J11: F | K11: F | L11: F | N11: 9 | O11: 1.25
A12: 590028353 | B12: Akhil Kumar | C12: T | D12: T | E12: F | F12: F | G12: T | H12: T | I12: F | J12: F | K12: F | L12: T | N12: 19 | O12: 13.75
A13: 590027987 | B13: Arpit Arpit | C13: T | D13: T | E13: T | F13: F | G13: T | H13: T | I13: F | J13: F | K13: T | L13: T | N13: 27 | O13: 23.75
A14: 590023231 | B14: Ayan Roy | C14: N | D14: N | E14: N | F14: N | G14: F | H14: N | I14: F | J14: N | K14: N | L14: N | N14: 0 | O14: -2
A15: 590028954 | B15: Bhavuk Kakkar | C15: T | D15: F | E15: F | F15: F | G15: F | H15: F | I15: F | J15: F | K15: F | L15: F | N15: 3 | O15: -6.25
A16: 590021623 | B16: Chandan Kumar | C16: T | D16: F | E16: T | F16: F | G16: N | H16: F | I16: F | J16: T | K16: F | L16: T | N16: 16 | O16: 10.75
A17: 590027316 | B17: Chimmay | C17: F | D17: T | E17: T | F17: F | G17: T | H17: F | I17: F | J17: T | K17: F | L17: T | N17: 19 | O17: 13.75
... A52: 590026540 | B52: Yashi Sharma | C52: T | D52: T | E52: N | F52: F | G52: T | H52: T | I52: T | J52: F | K52: T | L52: T | N52: 29 | O52: 27

Sheet Class Test 2
A1: Class Test 2
A2: =Marksheet!A2 -> Computational Techniques (CSEG 1023)
C3: CO3 | D3: CO3 | E3: CO3 | F3: CO3 | G3: CO3
A4: Student Id | B4: Name | C4: Q1 | D4: Q2 | E4: Q3 | F4: Q4 | G4: Q5 | H4: Q6 | I4: Q7 | J4: Q8 | K4: Q9 | L4: Q10 | M4: Q11 | N4: Total | O4: Sign
B5: Max Marks | C5: 8 | D5: 8 | E5: 8 | F5: 8 | G5: 8 | N5: =SUM(C5:H5) -> 40
A6: =Marksheet!C5 -> 590027532 | B6: =Marksheet!B5 -> Aanya Nautiyal | C6: 0 | D6: 0 | E6: 0 | F6: 0 | G6: 0 | N6: =SUM(C6:H6) -> 0
A7: =Marksheet!C6 -> 590021539 | B7: =Marksheet!B6 -> Aaryan Choubey | C7: 8 | D7: 5 | E7: 3 | F7: 5 | N7: =SUM(C7:H7) -> 21
A8: =Marksheet!C7 -> 590021092 | B8: =Marksheet!B7 -> Aarye Singhal | C8: 8 | D8: 5 | E8: 8 | F8: 4 | G8: 4 | N8: =SUM(C8:H8) -> 29
A9: =Marksheet!C8 -> 590028566 | B9: =Marksheet!B8 -> Abhijay | C9: 3 | D9: 4 | E9: 7 | F9: 4 | G9: 1 | N9: =SUM(C9:H9) -> 19
A10: =Marksheet!C9 -> 590027262 | B10: =Marksheet!B9 -> Adarsh Xavier Dadel | D10: 8 | E10: 3 | F10: 7 | N10: =SUM(C10:H10) -> 18
A11: =Marksheet!C10 -> 590025408 | B11: =Marksheet!B10 -> Aditya Guleriya | C11: 0 | D11: 0 | E11: 0 | F11: 0 | G11: 0 | N11: =SUM(C11:H11) -> 0
A12: =Marksheet!C11 -> 590028353 | B12: =Marksheet!B11 -> Akhil Kumar | C12: AB | N12: =SUM(C12:H12) -> 0
A13: =Marksheet!C12 -> 590027987 | B13: =Marksheet!B12 -> Arpit Arpit | E13: 4 | F13: 8 | N13: =SUM(C13:H13) -> 12
A14: =Marksheet!C13 -> 590023231 | B14: =Marksheet!B13 -> Ayan Roy | C14: 0 | N14: =SUM(C14:H14) -> 0
A15: =Marksheet!C14 -> 590028954 | B15: =Marksheet!B14 -> Bhavuk Kakkar | C15: 0 | G15: 0 | N15: =SUM(C15:H15) -> 0
A16: =Marksheet!C15 -> 590021623 | B16: =Marksheet!B15 -> Chandan Kumar | C16: 8 | F16: 6 | N16: =SUM(C16:H16) -> 14
A17: =Marksheet!C16 -> 590027316 | B17: =Marksheet!B16 -> Chimmay | D17: 7 | F17: 7 | N17: =SUM(C17:H17) -> 14
A18: =Marksheet!C17 -> 590021231 | B18: =Marksheet!B17 -> Dakshita Sharma | C18: 0 | D18: 5 | E18: 4 | F18: 5 | G18: 2 | N18: =SUM(C18:H18) -> 16
A19: =Marksheet!C18 -> 590020769 | B19: =Marksheet!B18 -> Dhairya Yogesh Gandhe | D19: 1 | E19: 4 | N19: =SUM(C19:H19) -> 5
A20: =Marksheet!C19 -> 590027689 | B20: =Marksheet!B19 -> Gerudra Pratap Sharma | C20: AB | N20: =SUM(C20:H20) -> 0
A21: =Marksheet!C20 -> 590028120 | B21: =Marksheet!B20 -> Harshit | C21: 0 | D21: 6 | E21: 4 | F21: 2 | N21: =SUM(C21:H21) -> 12
A22: =Marksheet!C21 -> 590029323 | B22: =Marksheet!B21 -> Hemant Kumar Patel | C22: 4 | E22: 2 | F22: 8 | N22: =SUM(C22:H22) -> 14
A23: =Marksheet!C22 -> 590025404 | B23: =Marksheet!B22 -> Irfan Mustafa Mir | C23: AB | N23: =SUM(C23:H23) -> 0
A24: =Marksheet!C23 -> 590024999 | B24: =Marksheet!B23 -> Keshav Dhumas | D24: 5 | E24: 4 | F24: 1 | N24: =SUM(C24:H24) -> 10
A25: =Marksheet!C24 -> 590028089 | B25: =Marksheet!B24 -> Krish Kumar | C25: 0 | D25: 0 | E25: 0 | F25: 0 | G25: 0 | N25: =SUM(C25:H25) -> 0
A26: =Marksheet!C25 -> 590029095 | B26: =Marksheet!B25 -> Kunal | C26: AB | N26: =SUM(C26:H26) -> 0
A27: =Marksheet!C26 -> 590021216 | B27: =Marksheet!B26 -> Mahak Makheja | D27: 5 | E27: 4 | F27: 1 | N27: =SUM(C27:H27) -> 10
A28: =Marksheet!C27 -> 590028121 | B28: =Marksheet!B27 -> Manasvi Dhaundiyal | D28: 6 | F28: 2 | G28: 8 | N28: =SUM(C28:H28) -> 16
A29: =Marksheet!C28 -> 590024606 | B29: =Marksheet!B28 -> Nainala Parthu | F29: 2 | N29: =SUM(C29:H29) -> 2
A30: =Marksheet!C29 -> 590024262 | B30: =Marksheet!B29 -> Navya Kwatra | C30: AB | N30: =SUM(C30:H30) -> 0
A31: =Marksheet!C30 -> 590021484 | B31: =Marksheet!B30 -> Navya Sagar | C31: 3 | D31: 4 | E31: 2 | N31: =SUM(C31:H31) -> 9
A32: =Marksheet!C31 -> 590027317 | B32: =Marksheet!B31 -> Onjoli G Shinde | C32: 0 | D32: 6 | E32: 4 | F32: 1 | G32: 4 | N32: =SUM(C32:H32) -> 15
A33: =Marksheet!C32 -> 590022345 | B33: =Marksheet!B32 -> Pakhi Dhanai | C33: 0 | D33: 6 | G33: 4 | N33: =SUM(C33:H33) -> 10
A34: =Marksheet!C33 -> 590028128 | B34: =Marksheet!B33 -> Prabhakar Singh | C34: 0 | D34: 4 | E34: 3 | F34: 8 | G34: 1 | N34: =SUM(C34:H34) -> 16
A35: =Marksheet!C34 -> 590027661 | B35: =Marksheet!B34 -> Rachit Bhatia | D35: 1 | N35: =SUM(C35:H35) -> 1
A36: =Marksheet!C35 -> 590024854 | B36: =Marksheet!B35 -> Ritika Saini | C36: 0 | D36: 6 | E36: 5 | F36: 6 | G36: 8 | N36: =SUM(C36:H36) -> 25
A37: =Marksheet!C36 -> 590027466 | B37: =Marksheet!B36 -> Rohit Tiwari | D37: 4 | G37: 2 | N37: =SUM(C37:H37) -> 6
A38: =Marksheet!C37 -> 590025203 | B38: =Marksheet!B37 -> Sachwlang Debbarma | C38: 0 | D38: 0 | E38: 0 | F38: 0 | G38: 0 | N38: =SUM(C38:H38) -> 0
A39: =Marksheet!C38 -> 590026536 | B39: =Marksheet!B38 -> Saksham Mahto | D39: 3 | E39: 3 | F39: 2 | N39: =SUM(C39:H39) -> 8
A40: =Marksheet!C39 -> 590024251 | B40: =Marksheet!B39 -> Samarjeet Lawankar | C40: 2 | D40: 1 | E40: 1 | N40: =SUM(C40:H40) -> 4
...

Sheet Final Presentation
A1: Final Presentation
A2: =Marksheet!A2 -> Computational Techniques (CSEG 1023)
A4: Student Id | B4: Name | C4: File | D4: Presentation | E4: Total | F4: Sign
B5: Max Marks | C5: 25 | D5: 25 | E5: =SUM(C5:D5) -> 50
A6: =Marksheet!C5 -> 590027532 | B6: =Marksheet!B5 -> Aanya Nautiyal | C6: 22 | D6: 19 | E6: =SUM(C6:D6) -> 41
A7: =Marksheet!C6 -> 590021539 | B7: =Marksheet!B6 -> Aaryan Choubey | C7: 23 | D7: 24 | E7: =SUM(C7:D7) -> 47
A8: =Marksheet!C7 -> 590021092 | B8: =Marksheet!B7 -> Aarye Singhal | C8: 21 | D8: 23 | E8: =SUM(C8:D8) -> 44
A9: =Marksheet!C8 -> 590028566 | B9: =Marksheet!B8 -> Abhijay | C9: 21 | D9: 24 | E9: =SUM(C9:D9) -> 45
A10: =Marksheet!C9 -> 590027262 | B10: =Marksheet!B9 -> Adarsh Xavier Dadel | C10: 22 | D10: 15 | E10: =SUM(C10:D10) -> 37
A11: =Marksheet!C10 -> 590025408 | B11: =Marksheet!B10 -> Aditya Guleriya | C11: 21 | D11: 20 | E11: =SUM(C11:D11) -> 41
A12: =Marksheet!C11 -> 590028353 | B12: =Marksheet!B11 -> Akhil Kumar | C12: AB | D12: AB | E12: =SUM(C12:D12) -> 0
A13: =Marksheet!C12 -> 590027987 | B13: =Marksheet!B12 -> Arpit Arpit | C13: 23 | D13: AB | E13: =SUM(C13:D13) -> 23
A14: =Marksheet!C13 -> 590023231 | B14: =Marksheet!B13 -> Ayan Roy | C14: 23 | D14: 22 | E14: =SUM(C14:D14) -> 45
A15: =Marksheet!C14 -> 590028954 | B15: =Marksheet!B14 -> Bhavuk Kakkar | C15: 23 | D15: 21 | E15: =SUM(C15:D15) -> 44
A16: =Marksheet!C15 -> 590021623 | B16: =Marksheet!B15 -> Chandan Kumar | C16: 23 | D16: 18 | E16: =SUM(C16:D16) -> 41
A17: =Marksheet!C16 -> 590027316 | B17: =Marksheet!B16 -> Chimmay | C17: 23 | D17: 23 | E17: =SUM(C17:D17) -> 46
A18: =Marksheet!C17 -> 590021231 | B18: =Marksheet!B17 -> Dakshita Sharma | C18: 23 | D18: 22 | E18: =SUM(C18:D18) -> 45
A19: =Marksheet!C18 -> 590020769 | B19: =Marksheet!B18 -> Dhairya Yogesh Gandhe | C19: 21 | D19: 20 | E19: =SUM(C19:D19) -> 41
A20: =Marksheet!C19 -> 590027689 | B20: =Marksheet!B19 -> Gerudra Pratap Sharma | C20: 23 | D20: 19 | E20: =SUM(C20:D20) -> 42
A21: =Marksheet!C20 -> 590028120 | B21: =Marksheet!B20 -> Harshit | C21: 21 | D21: 23 | E21: =SUM(C21:D21) -> 44
A22: =Marksheet!C21 -> 590029323 | B22: =Marksheet!B21 -> Hemant Kumar Patel | C22: 23 | D22: 19 | E22: =SUM(C22:D22) -> 42
A23: =Marksheet!C22 -> 590025404 | B23: =Marksheet!B22 -> Irfan Mustafa Mir | C23: AB | D23: AB | E23: =SUM(C23:D23) -> 0
A24: =Marksheet!C23 -> 590024999 | B24: =Marksheet!B23 -> Keshav Dhumas | C24: 23 | D24: 20 | E24: =SUM(C24:D24) -> 43
A25: =Marksheet!C24 -> 590028089 | B25: =Marksheet!B24 -> Krish Kumar | C25: 24 | D25: 21 | E25: =SUM(C25:D25) -> 45
A26: =Marksheet!C25 -> 590029095 | B26: =Marksheet!B25 -> Kunal | C26: 22 | D26: 15 | E26: =SUM(C26:D26) -> 37
A27: =Marksheet!C26 -> 590021216 | B27: =Marksheet!B26 -> Mahak Makheja | C27: 23 | D27: 19 | E27: =SUM(C27:D27) -> 42
A28: =Marksheet!C27 -> 590028121 | B28: =Marksheet!B27 -> Manasvi Dhaundiyal | C28: 23 | D28: 21 | E28: =SUM(C28:D28) -> 44
A29: =Marksheet!C28 -> 590024606 | B29: =Marksheet!B28 -> Nainala Parthu | C29: 24 | D29: 22 | E29: =SUM(C29:D29) -> 46
A30: =Marksheet!C29 -> 590024262 | B30: =Marksheet!B29 -> Navya Kwatra | C30: AB | D30: AB | E30: =SUM(C30:D30) -> 0
A31: =Marksheet!C30 -> 590021484 | B31: =Marksheet!B30 -> Navya Sagar | C31: 24 | D31: 23 | E31: =SUM(C31:D31) -> 47
A32: =Marksheet!C31 -> 590027317 | B32: =Marksheet!B31 -> Onjoli G Shinde | C32: 23 | D32: 23 | E32: =SUM(C32:D32) -> 46
A33: =Marksheet!C32 -> 590022345 | B33: =Marksheet!B32 -> Pakhi Dhanai | C33: 23 | D33: 21 | E33: =SUM(C33:D33) -> 44
A34: =Marksheet!C33 -> 590028128 | B34: =Marksheet!B33 -> Prabhakar Singh | C34: 21 | D34: 23 | E34: =SUM(C34:D34) -> 44
A35: =Marksheet!C34 -> 590027661 | B35: =Marksheet!B34 -> Rachit Bhatia | C35: 21 | D35: 24 | E35: =SUM(C35:D35) -> 45
A36: =Marksheet!C35 -> 590024854 | B36: =Marksheet!B35 -> Ritika Saini | C36: 23 | D36: 20 | E36: =SUM(C36:D36) -> 43
A37: =Marksheet!C36 -> 590027466 | B37: =Marksheet!B36 -> Rohit Tiwari | C37: 24 | D37: 20 | E37: =SUM(C37:D37) -> 44
A38: =Marksheet!C37 -> 590025203 | B38: =Marksheet!B37 -> Sachwlang Debbarma | C38: 24 | D38: 23 | E38: =SUM(C38:D38) -> 47
A39: =Marksheet!C38 -> 590026536 | B39: =Marksheet!B38 -> Saksham Mahto | C39: 21 | D39: 24 | E39: =SUM(C39:D39) -> 45
A40: =Marksheet!C39 -> 590024251 | B40: =Marksheet!B39 -> Samarjeet Lawankar | C40: 22 | D40: 21 | E40: =SUM(C40:D40) -> 43
A41: =Marksheet!C40 -> 590027669 | B41: =Marksheet!B40 -> Shivani Bajpai | C41: 23 | D41: 21 | E41: =SUM(C41:D41) -> 44
...
